Workbook
Name abcdefg: #REF!
Name Cavities: #REF!
Name Choose: #REF!
Name CONSTANTES: #REF!
Name CONSTANTS: #REF!
Name decoupled: #REF!
Name decoupled2: #REF!
Name degrees: #REF!
Name Document: #REF!
Name DPH: '(Linked) Hazard Risk Number HRN'!$B$6:$C$13
Name drytime: #REF!
Name eject: #REF!
Name EJECTPATT: #REF!
Name ejectpattern: #REF!
Name ejtpat: #REF!
Name fabulous: #REF!
Name fasdfsdfsd: #REF!
Name FE: '(Linked) Hazard Risk Number HRN'!$B$16:$C$26
Name Flow_transfer_mod: #REF!
Name FlowRatePlastic: #REF!
Name flowstudy: #REF!
Name Force: #REF!
Name formula: #REF!
Name g: #REF!
Name l: #REF!
Name Linear: #REF!
Name LO: '(Linked) Hazard Risk Number HRN'!$D$6:$E$14
Name machine: #REF!
Name MachineType: #REF!
Name Mfg: #REF!
Name Moldtype: #REF!
Name NP: '(Linked) Hazard Risk Number HRN'!$D$17:$E$22
Name OLE_LINK3: 'Portada del documento JDOC'!#REF!
Name PA: '(Linked) Hazard Risk Number HRN'!$D$25:$E$27
Name Piezo: #REF!
Name PLr: #REF!
Name position: #REF!
Name Press.: #REF!
Name presses: #REF!
Name Pressure: #REF!
Name Process: #REF!
Name process3: #REF!
Name processeng: #REF!
Name Recovery: #REF!
Name Resins: #REF!
Name Revision: #REF!
Name scale: #REF!
Name SDFASDFS: #REF!
Name sdsdgfasdg: #REF!
Name Security: #REF!
Name SPECHEAT: #REF!
Name Speed: #REF!
Name Table_Press: #REF!
Name tctype: #REF!
Name Temps: #REF!
Name Test: #REF!
Name therm2: #REF!
Name THERMAL: #REF!
Name Time: #REF!
Name Title: #REF!

Sheet Portada del documento JDOC
C1: 16-HS80-8000-00020 | E1: Revision
E2: B
C3: Evaluación de riesgos de maquinaria | E3: Categoría de documentación
E4: Obligatorio
A5: Aprobaciones | D5: Designación
A6: Chad McClimans | D6: Global Environmental Health & Safety Director
A7: Conor Kenny | D7: Sr Director Global Automation
A8: Detalles de la revisión (Nota: Consulte la información del documento del sistema para conocer la fecha de lanzamiento)
A9: Revision | B9: Detalles del cambio | E9: Autor
A10: A | B10: Lanzamiento inicial | E10: Guajana Skyers
A11: B | B11: Revisado al nuevo formulario de evaluación de riesgos de la máquina con hojas de apoyo. | E11: John Tebbe
A12: 1.0 Proposito
A13: El objetivo de la herramienta de evaluación de riesgos de máquinas (MRA) es respaldar la actividad de evaluación de riesgos proporcionando un método de evaluación coherente y completo. Una evaluación completa y conforme, que cumpla con las expectativas, garantizará que solo se utilicen equipos seguros en las operaciones antes de que cualquier equipo se libere en la célula de trabajo para la validación/calificación del proceso y/o la producción comercial. El proceso MRA pone a prueba el equipo evaluando los riesgos de seguridad/ergonomía que están presentes en el equipo durante su funcionamiento. Un Los sitios que ya cuentan con evaluaciones de riesgos de maquinaria deben realizar un análisis de deficiencias y subsanarlas. El objetivo es reducir el riesgo empresarial, proteger la salud y la seguridad de los empleados de Jabil, así como cumplir con los requisitos normativos y de los clientes.
A14: 2.0 Alcance
A15: Todos los sitios a nivel mundial que requieren un sistema de evaluación de riesgos de maquinaria según lo definido por la Norma de Seguridad de Maquinaria SE-ES20-00004. La mejor práctica para la evaluación inicial comienza durante la revisión del diseño, se reevalúa durante la construcción/prueba de aceptación de fábrica (FAT) y se reevalúa en la prueba de aceptación en el sitio (SAT) para nuevas construcciones, ya que se trata de un documento vivo.
A16: 3.0 Referencias
A17: Este documento debe utilizarse junto con los siguientes procedimientos:
A18: Numero de documento | C18: Document Title
A19: SE-ES20-00004 | C19: Estandar de seguridad en maquinaria
A20: 16-HS20-8000-00010 | C20: Procedimiento de seguridad en maquinaria
A21: 00-AT20-00001 | C21: Estandar de Introducción a la automatización de ensambles
A22: 4.0 Instrucciones
A23: 4.1 Revise la norma de seguridad de máquinas SE-ES20-00004 para conocer y comprender los requisitos mínimos de seguridad de máquinas de Jabil antes de seguir las instrucciones que se indican a continuación.
A24: Lea atentamente las instrucciones que figuran a continuación, así como las pestañas de referencia adicionales incluidas en el libro de trabajo. Las dos pestañas que deben utilizarse se describen en las secciones 4.4 y 4.5. Las secciones 4.7 a 4.9 son pestañas adicionales de apoyo para el análisis de datos, la presentación de informes y el seguimiento de las medidas destinadas a reducir los niveles de peligro residual que quedan tras la evaluación inicial.
A25: 4.1 Se espera que los centros utilicen este formulario MRA para documentar su evaluación. El MRA puede ser realizado por el contratista o por un tercero autorizado. Los centros que dispongan de un formulario o software equivalente que se considere que cumple o supera estos requisitos pueden solicitar su sustitución con la aprobación por escrito de los responsables de la aprobación de la plantilla anterior o de la persona designada.
A26: 4.2 Aunque los sitios web ofrecen una gran flexibilidad para añadir contenido y criterios para la evaluación de riesgos de la maquinaria, NO ELIMINE ni modifique ninguna fórmula, ponderación de factores o criterio del Índice de Riesgo de Peligro (HRN). El sitio web deberá revisar todos los peligros asociados a la máquina y las tareas relacionadas con la interacción con el equipo.
A27: 4.3. Se recomienda que el equipo de evaluación esté compuesto por entre 3 y 5 personas. Se debe calcular la media de cada aportación y votar si es necesario para acordar el HRN resultante, por lo que se recomienda que el número de miembros sea impar. Lo ideal es que los miembros del equipo que participen estén familiarizados con la tarea y la operación que se evalúa en su área de especialización. La MRA puede ser realizada por un contratista o un tercero autorizado, dependiendo de la complejidad del proyecto y/o de la disponibilidad del equipo competente en el lugar. El equipo puede cambiar en función de la condición de uso que se evalúe. A continuación se indican los requisitos mínimos para cada condición de uso o tarea de evaluación. - Operaciones normales: mínimo de (Medio Ambiente, Salud y Seguridad (EHS), Procesos/Automatización, Operaciones. - Manipulación de materiales: mínimo de EHS, Procesos/Automatización, Operaciones o tareas específicas de almacén. - Recuperación de fallos: mínimo de EHS, proceso/automatización, operaciones o tareas específicas de mantenimiento. - Mantenimiento correctivo/resolución de problemas: mínimo de EHS, proceso/automatización, operaciones o tareas específicas de mantenimiento. - Mantenimiento preventivo: mínimo EHS, procesos/automatización, mantenimiento/mecánica. - Modo de parada de emergencia/recuperación: mínimo EHS, procesos/automatización, operaciones o tareas específicas de mantenimiento. - Modo manual: mínimo EHS, procesos/automatización, mantenimiento/mecánica u operaciones específicas. - Arranque/apagado: mínimo EHS, proceso/automatización, mantenimiento/mecánica u operaciones específicas. - Bloqueo/prueba (LOTO): mínimo EHS, proceso/automatización, mantenimiento/mecánica. - Ajustes mecánicos: Mínimo EHS, proceso/automatización, mantenimiento/mecánica u operaciones específicas. - Configuración/cambio: Mínimo EHS, proceso/automatización, mantenimiento/mecánica u operaciones específicas.
A28: 4.4 Comience aquí_Cubierta_Pestaña de revisión
A29: 4.4A Introduzca el cliente, la ubicación del sitio, el número de proyecto/máquina, la fecha y el responsable en la parte superior.
A30: 4.4B Introduzca la versión, la fecha, el autor de la modificación y la descripción en la tabla del historial de revisiones de la evaluación. La primera revisión será la versión inicial. La evaluación es un documento vivo y el historial de revisiones se utiliza para documentar las actualizaciones posteriores a la evaluación inicial.
A31: 4.5 Pestaña de evaluación completa de MRA
A32: 4.5A Número de serie de entrada, fecha de fabricación, descripción de la máquina/línea o enfoque de la evaluación, ubicación de la planta del edificio en la parte superior de la evaluación.
A33: 4.5B Condiciones de uso (tarea) Este campo se puede rellenar manualmente o utilizar el menú desplegable para equipos más sencillos (personalizable en la pestaña Referencias del menú desplegable (vinculado)). Se recomienda incluir aquí suficiente información para que otras personas que no participen en la evaluación puedan seguirla con claridad. Ejemplo: Operaciones normales: Estación 01, carga de la carcasa, recogida y colocación. Utilice 4.3 como condiciones mínimas para evaluar, así como tener en cuenta todos los modos para los que está programado el equipo (automático, semiautomático, paso a paso, manual, jog). Pruebe físicamente el equipo, no se limite a comprobar que hay una cortina de luz y dar por sentado que los controles están en su sitio, sino que verifique que no se puede burlar ni dar acceso a peligros en la condición que se está evaluando.
... A38: 4.5G El nivel de riesgo y el índice de riesgo (HRN) se completarán automáticamente una vez que se hayan ponderado los cuatro elementos. El HRN inicial será alto, ya que se evalúa sin medidas de seguridad. El objetivo del cálculo del HRN es identificar los riesgos medios, altos e inaceptables que no son admisibles y determinar las medidas esenciales de reducción del riesgo para alcanzar un nivel de HRN aceptable. Esto se puede lograr reduciendo la probabilidad de sufrir daños o eliminando los peligros, la frecuencia o la exposición mediante un rediseño, ya sea reduciendo por separado o simultáneamente cada uno de los 4 elementos que determinan el riesgo asociado. Para obtener más información, consulte la pestaña de referencia del nivel de riesgo HRN (Ref.). A continuación se describen las expectativas mínimas de Jabil para un HRN aceptable y las acciones mínimas para un HRN medio/alto/inaceptable:
B39: 0 - 5 | C39: Riesgo insignificante | D39: Riesgo aceptable. No se requiere ninguna acción. Los usuarios finales deben seguir el manual del usuario, el procedimiento operativo estándar (SOP), las instrucciones de trabajo (WI), las ayudas visuales (VA), las señales de seguridad (pictogramas), la formación básica y el equipo de protección individual (EPI).
B40: >5 - 25 | C40: Riesgo bajo
B41: >25 - 50 | C41: Riesgo Medio | D41: Riesgo inaceptable. El centro deberá implementar medidas de control esenciales (evaluar soluciones de control de ingeniería sólidas, salvaguardias, etc., frente a medidas administrativas o EPI).
B42: >50 - 500 | C42: Riesgo Alto
B43: > 500 | C43: Riesgo inaceptable | D43: No es aceptable bajo ninguna circunstancia. La máquina no debe ponerse en funcionamiento. El sitio debe considerar un cambio en el diseño para que la máquina sea intrínsecamente segura y, a continuación, implementar las medidas de control esenciales.
A44: 4.5H IS0 13849-1 Clasificación del nivel de rendimiento (PLr). Esta sección puede dejarse en blanco para evaluaciones generales a nivel de sitio que NO construyan, integren, actualicen ni modifiquen equipos. Esta sección debe utilizarse con fabricantes de máquinas internos o externos, integradores (que conectan máquinas «listas para usar» y/o las unen entre sí como una línea o un sistema), actualizaciones o modificaciones. Se utiliza en la fase de diseño de la maquinaria, integridad máquina a máquina: el diseñador, integrador o ingeniero de procesos debe identificar el nivel de rendimiento requerido (PLr) de conformidad con la parte relacionada con la seguridad de los sistemas de control de la norma ISO 13849-1. Para ello, determine la probabilidad (P) según la sección de la norma ISO 13849 respondiendo a las 5 preguntas del menú desplegable. Debe completar el grado de daño posible (DPH) y la frecuencia de exposición a los peligros (FE) de la sección HRN de la evaluación inicial de riesgos para rellenar la gravedad (S) y la frecuencia (F). El nivel de rendimiento requerido (PLr) se rellenará automáticamente una vez que se hayan respondido las 5 preguntas. En función de los resultados, el PLr se rellenará automáticamente. Para obtener más información, consulte la pestaña de referencia del nivel de rendimiento PLr (Ref.).
...

Sheet Empezar aquí_Portada_Revisión
B1: Cliente | C1: Dexcom | H1: Ubicación | I1: Cuarto limpio Dexcom | L1: Fecha | M1: 03/30/2026
B2: Celula/ Numero de maquina: | C2: Autoline 5 | L2: Responsable: | M2: Brayan Escamilla
B4: Evaluación de riesgos de máquinas mediante el sistema de clasificación de peligros por números
B6: Tabla de revisión
B7: Version | C7: Fecha | E7: Modificado por | I7: Descripción de los cambios

Sheet MRA Evaluacion completa
B2: Nombre de máquina /Número | D2: =IF(ISBLANK('Empezar aquí_Portada_Revisión'!C2),"",'Empezar aquí_Portada_Revisión'!C2) -> Autoline 5 | E2: Serial #: | F2: 2131 | G2: Fecha MFG: | I2: 46111 | K2: Ubicación: | L2: =IF(ISBLANK('Empezar aquí_Portada_Revisión'!I1),"",'Empezar aquí_Portada_Revisión'!I1) -> Cuarto limpio Dexcom | Y2: Fecha: | Z2: ='Empezar aquí_Portada_Revisión'!$M$1 -> 03/30/2026
B3: Descripción de la máquina: | D3: Celda automatizada | K3: Ubicación del edificio/planta: | L3: Jabil Chihuahua | Y3: Por: | Z3: ='Empezar aquí_Portada_Revisión'!$M$2 -> Brayan Escamilla
B5: PELIGRO # | C5: Condición de uso (Tarea) | D5: Peligro(s) / Modo de fallo | E5: Imágenes | G5: Personas en riesgo | K5: EVALUACIÓN INICIAL - SIN SALVAGUARDAS / SIN PROTECCIÓN | N5: ISO 13849-1:2023 Evaluación inicial de HRN: DPH y FE rellenan automáticamente S y F | U5: CONTROLES PROPUESTOS PARA REDUCIR EL RIESGO A UN NIVEL ACEPTABLE | Y5: CONTROLES REALES IMPLEMENTADOS PARA REDUCIR EL RIESGO A UN NIVEL ACEPTABLE | AC5: CONTROLES REALES IMPLEMENTADOS PARA REDUCIR EL RIESGO A UN NIVEL ACEPTABLE
G6: Operador | H6: Mantenimiento | I6: Contratistas | J6: Otros | K6: Gravedad Frecuencia Probabilidad de ocurrencia Número de personas | L6: DPH FE LO NP | M6: Nivel de riesgo HRN | U6: Medida(s) de control ¡No puedes usar la evaluación de riesgos para reducir el grado de protección que exigen los estándares! | V6: Gravedad Frecuencia Probabilidad de ocurrencia Número de personas | W6: DPH FE LO NP | X6: Nivel de riesgo (HRN) | Y6: Medida(s) de control ¡No puedes usar la evaluación de riesgos para reducir el grado de protección que exigen los estándares! | Z6: Gravedad Frecuencia Probabilidad de ocurrencia Número de personas | AA6: DPH FE LO NP | AB6: Nivel de riesgo (HRN) | AC6: Medida(s) de control ¡No puedes usar la evaluación de riesgos para reducir el grado de protección que exigen los estándares! | AD6: Imagen | AE6: Gravedad Frecuencia Probabilidad de ocurrencia Número de personas | AF6: DPH FE LO NP | AG6: Nivel de riesgo (HRN)
E7: Imagen 1 | F7: Imagen 2 | N7: Determine la probabilidad P 13849-1 Avoidance | O7: Factor según la Tabla A.1 ISO 13849 estándar | P7: Count A-C from Factor table HIDDEN CELLS | S7: S F P | T7: PLr
B8: 1 | C8: Operación normal | D8: Mecánica: transmisión; pinchazo/aplastamiento/enredamiento. | G8: X | H8: X | K8: Moderado: Atención médica significativa como laceración severa y fisioterapia. Labores restringidas por menos de 2 semanas. | L8: =IF(ISBLANK(K8),"",VLOOKUP(K8,'(Linked) Hazard Risk Number HRN'!$B$6:$C$13,2,FALSE)) -> 4 | M8: =IF(M10="","",IF(M10>500,'(Linked) Hazard Risk Number HRN'!$C$37,IF(M10>50,'(Linked) Hazard Risk Number HRN'!$C$36,IF(M10>25,'(Linked) Hazard Risk Number HRN'!$C$35,IF(M10>5,'(Linked) Hazard Risk Number HRN'!$C$34,IF(M10>0,'(Linked) Hazard Risk Number HRN'!$C$33,"")))))) -> Riesgo Alto | N8: Persona calificada | O8: =IF(ISBLANK(N8),"",VLOOKUP(N8,'(Linked) PLr Probability Factor'!$B$7:$C$8,2,FALSE)) -> A | P8: C | Q8: =COUNTIF((O8:O12), "C") -> 0 | R8: =Q8 -> 0 | S8: =IF(ISBLANK(K8),"",IF(L8<2,"S1","S2")) -> S2 | U8: Detección de presencia: Añadir cortina de luz | V8: Insignificante: Sin primeros auxilios; rasguño o moretón. | W8: =IF(ISBLANK(V8),"",VLOOKUP(V8,'(Linked) Hazard Risk Number HRN'!$B$6:$C$13,2,FALSE)) -> 0.1 | X8: =IF(X10="","",IF(X10>500,'(Linked) Hazard Risk Number HRN'!$C$37,IF(X10>50,'(Linked) Hazard Risk Number HRN'!$C$36,IF(X10>25,'(Linked) Hazard Risk Number HRN'!$C$35,IF(X10>5,'(Linked) Hazard Risk Number HRN'!$C$34,IF(X10>0,'(Linked) Hazard Risk Number HRN'!$C$33,"")))))) -> Insignificante | Y8: Mantenimiento: Procedimiento/SOP/LOTO | Z8: Insignificante: Sin primeros auxilios; rasguño o moretón. | AA8: =IF(ISBLANK(Z8),"",VLOOKUP(Z8,'(Linked) Hazard Risk Number HRN'!$B$6:$C$13,2,FALSE)) -> 0.1 | AB8: =IF(AB10="","",IF(AB10>500,'(Linked) Hazard Risk Number HRN'!$C$37,IF(AB10>50,'(Linked) Hazard Risk Number HRN'!$C$36,IF(AB10>25,'(Linked) Hazard Risk Number HRN'!$C$35,IF(AB10>5,'(Linked) Hazard Risk Number HRN'!$C$34,IF(AB10>0,'(Linked) Hazard Risk Number HRN'!$C$33,"")))))) -> Insignificante | AC8: Detección de presencia: Añadir cortina de luz | AE8: Insignificante: Sin primeros auxilios; rasguño o moretón. | AF8: =IF(ISBLANK(AE8),"",VLOOKUP(AE8,'(Linked) Hazard Risk Number HRN'!$B$6:$C$13,2,FALSE)) -> 0.1 | AG8: =IF(AG10="","",IF(AG10>500,'(Linked) Hazard Risk Number HRN'!$C$37,IF(AG10>50,'(Linked) Hazard Risk Number HRN'!$C$36,IF(AG10>25,'(Linked) Hazard Risk Number HRN'!$C$35,IF(AG10>5,'(Linked) Hazard Risk Number HRN'!$C$34,IF(AG10>0,'(Linked) Hazard Risk Number HRN'!$C$33,"")))))) -> Insignificante
K9: De manera constante o más de una vez cada 15 minutos. | L9: =IF(ISBLANK(K9),"",VLOOKUP(K9,'(Linked) Hazard Risk Number HRN'!$B$16:$C$26,2,FALSE)) -> 5 | N9: Evento de baja o muy baja velocidad ej. <250 mm/s, tiempo para el peligro ≥3s y/o tiempo suficiente para escapar | O9: =IF(ISBLANK(N9),"",VLOOKUP(N9,'(Linked) PLr Probability Factor'!$B$12:$C$14,2,FALSE)) -> A | P9: B | Q9: =COUNTIF((O8:O12), "B") -> 0 | R9: =Q9 -> 0 | S9: =IF(ISBLANK(K9),"",IF(L9<5,"F1","F2")) -> F2 | V9: De manera constante o más de una vez cada 15 minutos. | W9: =IF(ISBLANK(V9),"",VLOOKUP(V9,'(Linked) Hazard Risk Number HRN'!$B$16:$C$26,2,FALSE)) -> 5 | Z9: Semanal | AA9: =IF(ISBLANK(Z9),"",VLOOKUP(Z9,'(Linked) Hazard Risk Number HRN'!$B$16:$C$26,2,FALSE)) -> 1.5 | AE9: De manera constante o más de una vez cada 15 minutos. | AF9: =IF(ISBLANK(AE9),"",VLOOKUP(AE9,'(Linked) Hazard Risk Number HRN'!$B$16:$C$26,2,FALSE)) -> 5
K10: Muy probable, es de esperarse | L10: =IF(ISBLANK(K10),"",VLOOKUP(K10,'(Linked) Hazard Risk Number HRN'!$D$6:$E$14,2,FALSE)) -> 10 | M10: =IF(OR(ISBLANK(K8),ISBLANK(K9),ISBLANK(K10),ISBLANK(K11)),"",L8*L9*L10*L11) -> 200 | N10: Facilmente posible posible en el 50% o mas de los casos | O10: =IF(ISBLANK(N10),"",VLOOKUP(N10,'(Linked) PLr Probability Factor'!$B$17:$C$20,2,FALSE)) -> A | P10: A | Q10: =COUNTIF((O8:O12), "A") -> 5 | R10: =Q10 -> 5 | T10: {=IF(OR(ISBLANK(K8),ISBLANK(K9),ISBLANK(N9),ISBLANK(N10),ISBLANK(N11)),"",INDEX(INDEX('(Linked) PLr Probability Factor'!C$33:$F$44,0,4),MATCH(S8&S9&S12,INDEX('(Linked) PLr Probability Factor'!C$33:$F$44,0,1)&INDEX('(Linked) PLr Probability Factor'!C$33:$F$44,0,2)&INDEX('(Linked) PLr Probability Factor'!C$33:$F$44,0,3),0)))} -> PLd | V10: Casi imposible, posible solo bajo circunstancias extremas | W10: =IF(ISBLANK(V10),"",VLOOKUP(V10,'(Linked) Hazard Risk Number HRN'!$D$6:$E$14,2,FALSE)) -> 0.033 | X10: =IF(OR(ISBLANK(V8),ISBLANK(V9),ISBLANK(V10),ISBLANK(V11)),"",W8*W9*W10*W11) -> 0.0165 | Z10: Casi imposible, posible solo bajo circunstancias extremas | AA10: =IF(ISBLANK(Z10),"",VLOOKUP(Z10,'(Linked) Hazard Risk Number HRN'!$D$6:$E$14,2,FALSE)) -> 0.033 | AB10: =IF(OR(ISBLANK(Z8),ISBLANK(Z9),ISBLANK(Z10),ISBLANK(Z11)),"",AA8*AA9*AA10*AA11) -> 0.00495 | AE10: Casi imposible, posible solo bajo circunstancias extremas | AF10: =IF(ISBLANK(AE10),"",VLOOKUP(AE10,'(Linked) Hazard Risk Number HRN'!$D$6:$E$14,2,FALSE)) -> 0.033 | AG10: =IF(OR(ISBLANK(AE8),ISBLANK(AE9),ISBLANK(AE10),ISBLANK(AE11)),"",AF8*AF9*AF10*AF11) -> 0.0165
K11: 1 a 2 personas | L11: =IF(ISBLANK(K11),"",VLOOKUP(K11,'(Linked) Hazard Risk Number HRN'!$D$17:$E$22,2,FALSE)) -> 1 | N11: Facil reconocimiento del peligro posible en el 50% o mas de los casos | O11: =IF(ISBLANK(N11),"",VLOOKUP(N11,'(Linked) PLr Probability Factor'!$B$23:$C$26,2,FALSE)) -> A | P11: Total | Q11: =SUM(R8:R10) -> 5 | R11: =Q11 -> 5 | V11: 1 a 2 personas | W11: =IF(ISBLANK(V11),"",VLOOKUP(V11,'(Linked) Hazard Risk Number HRN'!$D$17:$E$22,2,FALSE)) -> 1 | Z11: 1 a 2 personas | AA11: =IF(ISBLANK(Z11),"",VLOOKUP(Z11,'(Linked) Hazard Risk Number HRN'!$D$17:$E$22,2,FALSE)) -> 1 | AE11: 1 a 2 personas | AF11: =IF(ISBLANK(AE11),"",VLOOKUP(AE11,'(Linked) Hazard Risk Number HRN'!$D$17:$E$22,2,FALSE)) -> 1
N12: Baja complejidad ej, ajustar las abrazaderas de sujeción de la pieza de trabajo, o Interacción de muy baja complejidad o sin interacción ej, colocar una pieza de trabajo dentro de la máquina | O12: =IF(ISBLANK(N12),"",VLOOKUP(N12,'(Linked) PLr Probability Factor'!$B$29:$C$32,2,FALSE)) -> A | S12: =IF(OR(ISBLANK(N9),ISBLANK(N10),ISBLANK(N11)),"",IF(R8>0,"P2",IF(AND(R8=0,R9>2),"P2",IF(AND(R8=0,R9=2),"P2",IF(AND(R8=0,AND(R9<2,R10>1)),"P1"," "))))) -> P1
B13: 2 | C13: Mantenimiento preventivo | D13: Mecánico: ciclo automático/arranque repentino | H13: X | K13: Moderado: Atención médica significativa como laceración severa y fisioterapia. Labores restringidas por menos de 2 semanas. | L13: =IF(ISBLANK(K13),"",VLOOKUP(K13,'(Linked) Hazard Risk Number HRN'!$B$6:$C$13,2,FALSE)) -> 4 | M13: =IF(M15="","",IF(M15>500,'(Linked) Hazard Risk Number HRN'!$C$37,IF(M15>50,'(Linked) Hazard Risk Number HRN'!$C$36,IF(M15>25,'(Linked) Hazard Risk Number HRN'!$C$35,IF(M15>5,'(Linked) Hazard Risk Number HRN'!$C$34,IF(M15>0,'(Linked) Hazard Risk Number HRN'!$C$33,"")))))) -> Riesgo Alto | N13: Persona calificada | O13: =IF(ISBLANK(N13),"",VLOOKUP(N13,'(Linked) PLr Probability Factor'!$B$7:$C$8,2,FALSE)) -> A | P13: C | Q13: =COUNTIF((O13:O17), "C") -> 0 | R13: =Q13 -> 0 | S13: =IF(ISBLANK(K13),"",IF(L13<2,"S1","S2")) -> S2 | U13: Detección de presencia: Añadir cortina de luz | V13: Insignificante: Sin primeros auxilios; rasguño o moretón. | W13: =IF(ISBLANK(V13),"",VLOOKUP(V13,'(Linked) Hazard Risk Number HRN'!$B$6:$C$13,2,FALSE)) -> 0.1 | X13: =IF(X15="","",IF(X15>500,'(Linked) Hazard Risk Number HRN'!$C$37,IF(X15>50,'(Linked) Hazard Risk Number HRN'!$C$36,IF(X15>25,'(Linked) Hazard Risk Number HRN'!$C$35,IF(X15>5,'(Linked) Hazard Risk Number HRN'!$C$34,IF(X15>0,'(Linked) Hazard Risk Number HRN'!$C$33,"")))))) -> Insignificante | Y13: Mantenimiento: Procedimiento/SOP/LOTO | Z13: Insignificante: Sin primeros auxilios; rasguño o moretón. | AA13: =IF(ISBLANK(Z13),"",VLOOKUP(Z13,'(Linked) Hazard Risk Number HRN'!$B$6:$C$13,2,FALSE)) -> 0.1 | AB13: =IF(AB15="","",IF(AB15>500,'(Linked) Hazard Risk Number HRN'!$C$37,IF(AB15>50,'(Linked) Hazard Risk Number HRN'!$C$36,IF(AB15>25,'(Linked) Hazard Risk Number HRN'!$C$35,IF(AB15>5,'(Linked) Hazard Risk Number HRN'!$C$34,IF(AB15>0,'(Linked) Hazard Risk Number HRN'!$C$33,"")))))) -> Insignificante | AC13: Detección de presencia: Añadir cortina de luz | AE13: Insignificante: Sin primeros auxilios; rasguño o moretón. | AF13: =IF(ISBLANK(AE13),"",VLOOKUP(AE13,'(Linked) Hazard Risk Number HRN'!$B$6:$C$13,2,FALSE)) -> 0.1 | AG13: =IF(AG15="","",IF(AG15>500,'(Linked) Hazard Risk Number HRN'!$C$37,IF(AG15>50,'(Linked) Hazard Risk Number HRN'!$C$36,IF(AG15>25,'(Linked) Hazard Risk Number HRN'!$C$35,IF(AG15>5,'(Linked) Hazard Risk Number HRN'!$C$34,IF(AG15>0,'(Linked) Hazard Risk Number HRN'!$C$33,"")))))) -> Insignificante
K14: Semanal | L14: =IF(ISBLANK(K14),"",VLOOKUP(K14,'(Linked) Hazard Risk Number HRN'!$B$16:$C$26,2,FALSE)) -> 1.5 | N14: Evento de baja o muy baja velocidad ej. <250 mm/s, tiempo para el peligro ≥3s y/o tiempo suficiente para escapar | O14: =IF(ISBLANK(N14),"",VLOOKUP(N14,'(Linked) PLr Probability Factor'!$B$12:$C$14,2,FALSE)) -> A | P14: B | Q14: =COUNTIF((O13:O17), "B") -> 0 | R14: =Q14 -> 0 | S14: =IF(ISBLANK(K14),"",IF(L14<5,"F1","F2")) -> F1 | V14: Semanal | W14: =IF(ISBLANK(V14),"",VLOOKUP(V14,'(Linked) Hazard Risk Number HRN'!$B$16:$C$26,2,FALSE)) -> 1.5 | Z14: Semanal | AA14: =IF(ISBLANK(Z14),"",VLOOKUP(Z14,'(Linked) Hazard Risk Number HRN'!$B$16:$C$26,2,FALSE)) -> 1.5 | AE14: Semanal | AF14: =IF(ISBLANK(AE14),"",VLOOKUP(AE14,'(Linked) Hazard Risk Number HRN'!$B$16:$C$26,2,FALSE)) -> 1.5
K15: Muy probable, es de esperarse | L15: =IF(ISBLANK(K15),"",VLOOKUP(K15,'(Linked) Hazard Risk Number HRN'!$D$6:$E$14,2,FALSE)) -> 10 | M15: =IF(OR(ISBLANK(K13),ISBLANK(K14),ISBLANK(K15),ISBLANK(K16)),"",L13*L14*L15*L16) -> 60 | N15: Facilmente posible posible en el 50% o mas de los casos | O15: =IF(ISBLANK(N15),"",VLOOKUP(N15,'(Linked) PLr Probability Factor'!$B$17:$C$20,2,FALSE)) -> A | P15: A | Q15: =COUNTIF((O13:O17), "A") -> 5 | R15: =Q15 -> 5 | T15: {=IF(OR(ISBLANK(K13),ISBLANK(K14),ISBLANK(N14),ISBLANK(N15),ISBLANK(N16)),"",INDEX(INDEX('(Linked) PLr Probability Factor'!C$33:$F$44,0,4),MATCH(S13&S14&S17,INDEX('(Linked) PLr Probability Factor'!C$33:$F$44,0,1)&INDEX('(Linked) PLr Probability Factor'!C$33:$F$44,0,2)&INDEX('(Linked) PLr Probability Factor'!C$33:$F$44,0,3),0)))} -> PLc | V15: Casi imposible, posible solo bajo circunstancias extremas | W15: =IF(ISBLANK(V15),"",VLOOKUP(V15,'(Linked) Hazard Risk Number HRN'!$D$6:$E$14,2,FALSE)) -> 0.033 | X15: =IF(OR(ISBLANK(V13),ISBLANK(V14),ISBLANK(V15),ISBLANK(V16)),"",W13*W14*W15*W16) -> 0.00495 | Z15: Casi imposible, posible solo bajo circunstancias extremas | AA15: =IF(ISBLANK(Z15),"",VLOOKUP(Z15,'(Linked) Hazard Risk Number HRN'!$D$6:$E$14,2,FALSE)) -> 0.033 | AB15: =IF(OR(ISBLANK(Z13),ISBLANK(Z14),ISBLANK(Z15),ISBLANK(Z16)),"",AA13*AA14*AA15*AA16) -> 0.00495 | AE15: Casi imposible, posible solo bajo circunstancias extremas | AF15: =IF(ISBLANK(AE15),"",VLOOKUP(AE15,'(Linked) Hazard Risk Number HRN'!$D$6:$E$14,2,FALSE)) -> 0.033 | AG15: =IF(OR(ISBLANK(AE13),ISBLANK(AE14),ISBLANK(AE15),ISBLANK(AE16)),"",AF13*AF14*AF15*AF16) -> 0.00495
K16: 1 a 2 personas | L16: =IF(ISBLANK(K16),"",VLOOKUP(K16,'(Linked) Hazard Risk Number HRN'!$D$17:$E$22,2,FALSE)) -> 1 | N16: Facil reconocimiento del peligro posible en el 50% o mas de los casos | O16: =IF(ISBLANK(N16),"",VLOOKUP(N16,'(Linked) PLr Probability Factor'!$B$23:$C$26,2,FALSE)) -> A | P16: Total | Q16: =SUM(R13:R15) -> 5 | R16: =Q16 -> 5 | V16: 1 a 2 personas | W16: =IF(ISBLANK(V16),"",VLOOKUP(V16,'(Linked) Hazard Risk Number HRN'!$D$17:$E$22,2,FALSE)) -> 1 | Z16: 1 a 2 personas | AA16: =IF(ISBLANK(Z16),"",VLOOKUP(Z16,'(Linked) Hazard Risk Number HRN'!$D$17:$E$22,2,FALSE)) -> 1 | AE16: 1 a 2 personas | AF16: =IF(ISBLANK(AE16),"",VLOOKUP(AE16,'(Linked) Hazard Risk Number HRN'!$D$17:$E$22,2,FALSE)) -> 1
N17: Baja complejidad ej, ajustar las abrazaderas de sujeción de la pieza de trabajo, o Interacción de muy baja complejidad o sin interacción ej, colocar una pieza de trabajo dentro de la máquina | O17: =IF(ISBLANK(N17),"",VLOOKUP(N17,'(Linked) PLr Probability Factor'!$B$29:$C$32,2,FALSE)) -> A | S17: =IF(OR(ISBLANK(N14),ISBLANK(N15),ISBLANK(N16)),"",IF(R13>0,"P2",IF(AND(R13=0,R14>2),"P2",IF(AND(R13=0,R14=2),"P2",IF(AND(R13=0,AND(R14<2,R15>1)),"P1"," "))))) -> P1
A18: | | B18: 3 | C18: Operación normal | D18: Mecánica: transmisión; pinchazo/aplastamiento/enredamiento. | G18: X | H18: X | K18: Moderado: Atención médica significativa como laceración severa y fisioterapia. Labores restringidas por menos de 2 semanas. | L18: =IF(ISBLANK(K18),"",VLOOKUP(K18,'(Linked) Hazard Risk Number HRN'!$B$6:$C$13,2,FALSE)) -> 4 | M18: =IF(M20="","",IF(M20>500,'(Linked) Hazard Risk Number HRN'!$C$37,IF(M20>50,'(Linked) Hazard Risk Number HRN'!$C$36,IF(M20>25,'(Linked) Hazard Risk Number HRN'!$C$35,IF(M20>5,'(Linked) Hazard Risk Number HRN'!$C$34,IF(M20>0,'(Linked) Hazard Risk Number HRN'!$C$33,"")))))) -> Riesgo Alto | N18: Persona calificada | O18: =IF(ISBLANK(N18),"",VLOOKUP(N18,'(Linked) PLr Probability Factor'!$B$7:$C$8,2,FALSE)) -> A | P18: C | Q18: =COUNTIF((O18:O22), "C") -> 0 | R18: =Q18 -> 0 | S18: =IF(ISBLANK(K18),"",IF(L18<2,"S1","S2")) -> S2 | U18: Detección de presencia: Añadir cortina de luz | V18: Insignificante: Sin primeros auxilios; rasguño o moretón. | W18: =IF(ISBLANK(V18),"",VLOOKUP(V18,'(Linked) Hazard Risk Number HRN'!$B$6:$C$13,2,FALSE)) -> 0.1 | X18: =IF(X20="","",IF(X20>500,'(Linked) Hazard Risk Number HRN'!$C$37,IF(X20>50,'(Linked) Hazard Risk Number HRN'!$C$36,IF(X20>25,'(Linked) Hazard Risk Number HRN'!$C$35,IF(X20>5,'(Linked) Hazard Risk Number HRN'!$C$34,IF(X20>0,'(Linked) Hazard Risk Number HRN'!$C$33,"")))))) -> Insignificante | Y18: Mantenimiento: Procedimiento/SOP/LOTO | Z18: Insignificante: Sin primeros auxilios; rasguño o moretón. | AA18: =IF(ISBLANK(Z18),"",VLOOKUP(Z18,'(Linked) Hazard Risk Number HRN'!$B$6:$C$13,2,FALSE)) -> 0.1 | AB18: =IF(AB20="","",IF(AB20>500,'(Linked) Hazard Risk Number HRN'!$C$37,IF(AB20>50,'(Linked) Hazard Risk Number HRN'!$C$36,IF(AB20>25,'(Linked) Hazard Risk Number HRN'!$C$35,IF(AB20>5,'(Linked) Hazard Risk Number HRN'!$C$34,IF(AB20>0,'(Linked) Hazard Risk Number HRN'!$C$33,"")))))) -> Insignificante | AC18: Detección de presencia: Añadir cortina de luz | AE18: Insignificante: Sin primeros auxilios; rasguño o moretón. | AF18: =IF(ISBLANK(AE18),"",VLOOKUP(AE18,'(Linked) Hazard Risk Number HRN'!$B$6:$C$13,2,FALSE)) -> 0.1 | AG18: =IF(AG20="","",IF(AG20>500,'(Linked) Hazard Risk Number HRN'!$C$37,IF(AG20>50,'(Linked) Hazard Risk Number HRN'!$C$36,IF(AG20>25,'(Linked) Hazard Risk Number HRN'!$C$35,IF(AG20>5,'(Linked) Hazard Risk Number HRN'!$C$34,IF(AG20>0,'(Linked) Hazard Risk Number HRN'!$C$33,"")))))) -> Insignificante
K19: De manera constante o más de una vez cada 15 minutos. | L19: =IF(ISBLANK(K19),"",VLOOKUP(K19,'(Linked) Hazard Risk Number HRN'!$B$16:$C$26,2,FALSE)) -> 5 | N19: Evento de baja o muy baja velocidad ej. <250 mm/s, tiempo para el peligro ≥3s y/o tiempo suficiente para escapar | O19: =IF(ISBLANK(N19),"",VLOOKUP(N19,'(Linked) PLr Probability Factor'!$B$12:$C$14,2,FALSE)) -> A | P19: B | Q19: =COUNTIF((O18:O22), "B") -> 0 | R19: =Q19 -> 0 | S19: =IF(ISBLANK(K19),"",IF(L19<5,"F1","F2")) -> F2 | V19: De manera constante o más de una vez cada 15 minutos. | W19: =IF(ISBLANK(V19),"",VLOOKUP(V19,'(Linked) Hazard Risk Number HRN'!$B$16:$C$26,2,FALSE)) -> 5 | Z19: De manera constante o más de una vez cada 15 minutos. | AA19: =IF(ISBLANK(Z19),"",VLOOKUP(Z19,'(Linked) Hazard Risk Number HRN'!$B$16:$C$26,2,FALSE)) -> 5 | AE19: De manera constante o más de una vez cada 15 minutos. | AF19: =IF(ISBLANK(AE19),"",VLOOKUP(AE19,'(Linked) Hazard Risk Number HRN'!$B$16:$C$26,2,FALSE)) -> 5
K20: Muy probable, es de esperarse | L20: =IF(ISBLANK(K20),"",VLOOKUP(K20,'(Linked) Hazard Risk Number HRN'!$D$6:$E$14,2,FALSE)) -> 10 | M20: =IF(OR(ISBLANK(K18),ISBLANK(K19),ISBLANK(K20),ISBLANK(K21)),"",L18*L19*L20*L21) -> 200 | N20: Facilmente posible posible en el 50% o mas de los casos | O20: =IF(ISBLANK(N20),"",VLOOKUP(N20,'(Linked) PLr Probability Factor'!$B$17:$C$20,2,FALSE)) -> A | P20: A | Q20: =COUNTIF((O18:O22), "A") -> 5 | R20: =Q20 -> 5 | T20: {=IF(OR(ISBLANK(K18),ISBLANK(K19),ISBLANK(N19),ISBLANK(N20),ISBLANK(N21)),"",INDEX(INDEX('(Linked) PLr Probability Factor'!C$33:$F$44,0,4),MATCH(S18&S19&S22,INDEX('(Linked) PLr Probability Factor'!C$33:$F$44,0,1)&INDEX('(Linked) PLr Probability Factor'!C$33:$F$44,0,2)&INDEX('(Linked) PLr Probability Factor'!C$33:$F$44,0,3),0)))} -> PLd | V20: Casi imposible, posible solo bajo circunstancias extremas | W20: =IF(ISBLANK(V20),"",VLOOKUP(V20,'(Linked) Hazard Risk Number HRN'!$D$6:$E$14,2,FALSE)) -> 0.033 | X20: =IF(OR(ISBLANK(V18),ISBLANK(V19),ISBLANK(V20),ISBLANK(V21)),"",W18*W19*W20*W21) -> 0.0165 | Z20: Casi imposible, posible solo bajo circunstancias extremas | AA20: =IF(ISBLANK(Z20),"",VLOOKUP(Z20,'(Linked) Hazard Risk Number HRN'!$D$6:$E$14,2,FALSE)) -> 0.033 | AB20: =IF(OR(ISBLANK(Z18),ISBLANK(Z19),ISBLANK(Z20),ISBLANK(Z21)),"",AA18*AA19*AA20*AA21) -> 0.0165 | AE20: Casi imposible, posible solo bajo circunstancias extremas | AF20: =IF(ISBLANK(AE20),"",VLOOKUP(AE20,'(Linked) Hazard Risk Number HRN'!$D$6:$E$14,2,FALSE)) -> 0.033 | AG20: =IF(OR(ISBLANK(AE18),ISBLANK(AE19),ISBLANK(AE20),ISBLANK(AE21)),"",AF18*AF19*AF20*AF21) -> 0.0165
K21: 1 a 2 personas | L21: =IF(ISBLANK(K21),"",VLOOKUP(K21,'(Linked) Hazard Risk Number HRN'!$D$17:$E$22,2,FALSE)) -> 1 | N21: Facil reconocimiento del peligro posible en el 50% o mas de los casos | O21: =IF(ISBLANK(N21),"",VLOOKUP(N21,'(Linked) PLr Probability Factor'!$B$23:$C$26,2,FALSE)) -> A | P21: Total | Q21: =SUM(R18:R20) -> 5 | R21: =Q21 -> 5 | V21: 1 a 2 personas | W21: =IF(ISBLANK(V21),"",VLOOKUP(V21,'(Linked) Hazard Risk Number HRN'!$D$17:$E$22,2,FALSE)) -> 1 | Z21: 1 a 2 personas | AA21: =IF(ISBLANK(Z21),"",VLOOKUP(Z21,'(Linked) Hazard Risk Number HRN'!$D$17:$E$22,2,FALSE)) -> 1 | AE21: 1 a 2 personas | AF21: =IF(ISBLANK(AE21),"",VLOOKUP(AE21,'(Linked) Hazard Risk Number HRN'!$D$17:$E$22,2,FALSE)) -> 1
N22: Baja complejidad ej, ajustar las abrazaderas de sujeción de la pieza de trabajo, o Interacción de muy baja complejidad o sin interacción ej, colocar una pieza de trabajo dentro de la máquina | O22: =IF(ISBLANK(N22),"",VLOOKUP(N22,'(Linked) PLr Probability Factor'!$B$29:$C$32,2,FALSE)) -> A | S22: =IF(OR(ISBLANK(N19),ISBLANK(N20),ISBLANK(N21)),"",IF(R18>0,"P2",IF(AND(R18=0,R19>2),"P2",IF(AND(R18=0,R19=2),"P2",IF(AND(R18=0,AND(R19<2,R20>1)),"P1"," "))))) -> P1
B23: 4 | C23: Mantenimiento preventivo | D23: Sistema de control: ciclo automático/arranque inesperado | H23: X | K23: Moderado: Atención médica significativa como laceración severa y fisioterapia. Labores restringidas por menos de 2 semanas. | L23: =IF(ISBLANK(K23),"",VLOOKUP(K23,'(Linked) Hazard Risk Number HRN'!$B$6:$C$13,2,FALSE)) -> 4 | M23: =IF(M25="","",IF(M25>500,'(Linked) Hazard Risk Number HRN'!$C$37,IF(M25>50,'(Linked) Hazard Risk Number HRN'!$C$36,IF(M25>25,'(Linked) Hazard Risk Number HRN'!$C$35,IF(M25>5,'(Linked) Hazard Risk Number HRN'!$C$34,IF(M25>0,'(Linked) Hazard Risk Number HRN'!$C$33,"")))))) -> Riesgo Alto | N23: Persona calificada | O23: =IF(ISBLANK(N23),"",VLOOKUP(N23,'(Linked) PLr Probability Factor'!$B$7:$C$8,2,FALSE)) -> A | P23: C | Q23: =COUNTIF((O23:O27), "C") -> 0 | R23: =Q23 -> 0 | S23: =IF(ISBLANK(K23),"",IF(L23<2,"S1","S2")) -> S2 | U23: Detección de presencia: Añadir cortina de luz | V23: Insignificante: Sin primeros auxilios; rasguño o moretón. | W23: =IF(ISBLANK(V23),"",VLOOKUP(V23,'(Linked) Hazard Risk Number HRN'!$B$6:$C$13,2,FALSE)) -> 0.1 | X23: =IF(X25="","",IF(X25>500,'(Linked) Hazard Risk Number HRN'!$C$37,IF(X25>50,'(Linked) Hazard Risk Number HRN'!$C$36,IF(X25>25,'(Linked) Hazard Risk Number HRN'!$C$35,IF(X25>5,'(Linked) Hazard Risk Number HRN'!$C$34,IF(X25>0,'(Linked) Hazard Risk Number HRN'!$C$33,"")))))) -> Insignificante | Y23: Mantenimiento: Procedimiento/SOP/LOTO | Z23: Insignificante: Sin primeros auxilios; rasguño o moretón. | AA23: =IF(ISBLANK(Z23),"",VLOOKUP(Z23,'(Linked) Hazard Risk Number HRN'!$B$6:$C$13,2,FALSE)) -> 0.1 | AB23: =IF(AB25="","",IF(AB25>500,'(Linked) Hazard Risk Number HRN'!$C$37,IF(AB25>50,'(Linked) Hazard Risk Number HRN'!$C$36,IF(AB25>25,'(Linked) Hazard Risk Number HRN'!$C$35,IF(AB25>5,'(Linked) Hazard Risk Number HRN'!$C$34,IF(AB25>0,'(Linked) Hazard Risk Number HRN'!$C$33,"")))))) -> Insignificante | AC23: Detección de presencia: Añadir cortina de luz | AE23: Insignificante: Sin primeros auxilios; rasguño o moretón. | AF23: =IF(ISBLANK(AE23),"",VLOOKUP(AE23,'(Linked) Hazard Risk Number HRN'!$B$6:$C$13,2,FALSE)) -> 0.1 | AG23: =IF(AG25="","",IF(AG25>500,'(Linked) Hazard Risk Number HRN'!$C$37,IF(AG25>50,'(Linked) Hazard Risk Number HRN'!$C$36,IF(AG25>25,'(Linked) Hazard Risk Number HRN'!$C$35,IF(AG25>5,'(Linked) Hazard Risk Number HRN'!$C$34,IF(AG25>0,'(Linked) Hazard Risk Number HRN'!$C$33,"")))))) -> Insignificante
K24: Semanal | L24: =IF(ISBLANK(K24),"",VLOOKUP(K24,'(Linked) Hazard Risk Number HRN'!$B$16:$C$26,2,FALSE)) -> 1.5 | N24: Evento de baja o muy baja velocidad ej. <250 mm/s, tiempo para el peligro ≥3s y/o tiempo suficiente para escapar | O24: =IF(ISBLANK(N24),"",VLOOKUP(N24,'(Linked) PLr Probability Factor'!$B$12:$C$14,2,FALSE)) -> A | P24: B | Q24: =COUNTIF((O23:O27), "B") -> 0 | R24: =Q24 -> 0 | S24: =IF(ISBLANK(K24),"",IF(L24<5,"F1","F2")) -> F1 | V24: Semanal | W24: =IF(ISBLANK(V24),"",VLOOKUP(V24,'(Linked) Hazard Risk Number HRN'!$B$16:$C$26,2,FALSE)) -> 1.5 | Z24: Semanal | AA24: =IF(ISBLANK(Z24),"",VLOOKUP(Z24,'(Linked) Hazard Risk Number HRN'!$B$16:$C$26,2,FALSE)) -> 1.5 | AE24: Semanal | AF24: =IF(ISBLANK(AE24),"",VLOOKUP(AE24,'(Linked) Hazard Risk Number HRN'!$B$16:$C$26,2,FALSE)) -> 1.5
K25: Muy probable, es de esperarse | L25: =IF(ISBLANK(K25),"",VLOOKUP(K25,'(Linked) Hazard Risk Number HRN'!$D$6:$E$14,2,FALSE)) -> 10 | M25: =IF(OR(ISBLANK(K23),ISBLANK(K24),ISBLANK(K25),ISBLANK(K26)),"",L23*L24*L25*L26) -> 60 | N25: Facilmente posible posible en el 50% o mas de los casos | O25: =IF(ISBLANK(N25),"",VLOOKUP(N25,'(Linked) PLr Probability Factor'!$B$17:$C$20,2,FALSE)) -> A | P25: A | Q25: =COUNTIF((O23:O27), "A") -> 5 | R25: =Q25 -> 5 | T25: {=IF(OR(ISBLANK(K23),ISBLANK(K24),ISBLANK(N24),ISBLANK(N25),ISBLANK(N26)),"",INDEX(INDEX('(Linked) PLr Probability Factor'!C$33:$F$44,0,4),MATCH(S23&S24&S27,INDEX('(Linked) PLr Probability Factor'!C$33:$F$44,0,1)&INDEX('(Linked) PLr Probability Factor'!C$33:$F$44,0,2)&INDEX('(Linked) PLr Probability Factor'!C$33:$F$44,0,3),0)))} -> PLc | V25: Casi imposible, posible solo bajo circunstancias extremas | W25: =IF(ISBLANK(V25),"",VLOOKUP(V25,'(Linked) Hazard Risk Number HRN'!$D$6:$E$14,2,FALSE)) -> 0.033 | X25: =IF(OR(ISBLANK(V23),ISBLANK(V24),ISBLANK(V25),ISBLANK(V26)),"",W23*W24*W25*W26) -> 0.00495 | Z25: Casi imposible, posible solo bajo circunstancias extremas | AA25: =IF(ISBLANK(Z25),"",VLOOKUP(Z25,'(Linked) Hazard Risk Number HRN'!$D$6:$E$14,2,FALSE)) -> 0.033 | AB25: =IF(OR(ISBLANK(Z23),ISBLANK(Z24),ISBLANK(Z25),ISBLANK(Z26)),"",AA23*AA24*AA25*AA26) -> 0.00495 | AE25: Casi imposible, posible solo bajo circunstancias extremas | AF25: =IF(ISBLANK(AE25),"",VLOOKUP(AE25,'(Linked) Hazard Risk Number HRN'!$D$6:$E$14,2,FALSE)) -> 0.033 | AG25: =IF(OR(ISBLANK(AE23),ISBLANK(AE24),ISBLANK(AE25),ISBLANK(AE26)),"",AF23*AF24*AF25*AF26) -> 0.00495
K26: 1 a 2 personas | L26: =IF(ISBLANK(K26),"",VLOOKUP(K26,'(Linked) Hazard Risk Number HRN'!$D$17:$E$22,2,FALSE)) -> 1 | N26: Facil reconocimiento del peligro posible en el 50% o mas de los casos | O26: =IF(ISBLANK(N26),"",VLOOKUP(N26,'(Linked) PLr Probability Factor'!$B$23:$C$26,2,FALSE)) -> A | P26: Total | Q26: =SUM(R23:R25) -> 5 | R26: =Q26 -> 5 | V26: 1 a 2 personas | W26: =IF(ISBLANK(V26),"",VLOOKUP(V26,'(Linked) Hazard Risk Number HRN'!$D$17:$E$22,2,FALSE)) -> 1 | Z26: 1 a 2 personas | AA26: =IF(ISBLANK(Z26),"",VLOOKUP(Z26,'(Linked) Hazard Risk Number HRN'!$D$17:$E$22,2,FALSE)) -> 1 | AE26: 1 a 2 personas | AF26: =IF(ISBLANK(AE26),"",VLOOKUP(AE26,'(Linked) Hazard Risk Number HRN'!$D$17:$E$22,2,FALSE)) -> 1
N27: Baja complejidad ej, ajustar las abrazaderas de sujeción de la pieza de trabajo, o Interacción de muy baja complejidad o sin interacción ej, colocar una pieza de trabajo dentro de la máquina | O27: =IF(ISBLANK(N27),"",VLOOKUP(N27,'(Linked) PLr Probability Factor'!$B$29:$C$32,2,FALSE)) -> A | S27: =IF(OR(ISBLANK(N24),ISBLANK(N25),ISBLANK(N26)),"",IF(R23>0,"P2",IF(AND(R23=0,R24>2),"P2",IF(AND(R23=0,R24=2),"P2",IF(AND(R23=0,AND(R24<2,R25>1)),"P1"," "))))) -> P1
B28: 5 | C28: Operación normal | D28: Sistema de control: ciclo automático/arranque inesperado | H28: X | K28: Mayor: Lesión grave, fractura ósea o cirugía general; incapacidad laboral documentada. Labores restringidas por más de 2 semanas y menos de 6 meses. | L28: =IF(ISBLANK(K28),"",VLOOKUP(K28,'(Linked) Hazard Risk Number HRN'!$B$6:$C$13,2,FALSE)) -> 6 | M28: =IF(M30="","",IF(M30>500,'(Linked) Hazard Risk Number HRN'!$C$37,IF(M30>50,'(Linked) Hazard Risk Number HRN'!$C$36,IF(M30>25,'(Linked) Hazard Risk Number HRN'!$C$35,IF(M30>5,'(Linked) Hazard Risk Number HRN'!$C$34,IF(M30>0,'(Linked) Hazard Risk Number HRN'!$C$33,"")))))) -> Riesgo Alto | N28: Persona calificada | O28: =IF(ISBLANK(N28),"",VLOOKUP(N28,'(Linked) PLr Probability Factor'!$B$7:$C$8,2,FALSE)) -> A | P28: C | Q28: =COUNTIF((O28:O32), "C") -> 1 | R28: =Q28 -> 1 | S28: =IF(ISBLANK(K28),"",IF(L28<2,"S1","S2")) -> S2 | U28: Protección/puerta móvil: Añadir nueva, con Interlocked | V28: Insignificante: Sin primeros auxilios; rasguño o moretón. | W28: =IF(ISBLANK(V28),"",VLOOKUP(V28,'(Linked) Hazard Risk Number HRN'!$B$6:$C$13,2,FALSE)) -> 0.1 | X28: =IF(X30="","",IF(X30>500,'(Linked) Hazard Risk Number HRN'!$C$37,IF(X30>50,'(Linked) Hazard Risk Number HRN'!$C$36,IF(X30>25,'(Linked) Hazard Risk Number HRN'!$C$35,IF(X30>5,'(Linked) Hazard Risk Number HRN'!$C$34,IF(X30>0,'(Linked) Hazard Risk Number HRN'!$C$33,"")))))) -> Insignificante | Y28: Mantenimiento: Procedimiento/SOP/LOTO | Z28: Insignificante: Sin primeros auxilios; rasguño o moretón. | AA28: =IF(ISBLANK(Z28),"",VLOOKUP(Z28,'(Linked) Hazard Risk Number HRN'!$B$6:$C$13,2,FALSE)) -> 0.1 | AB28: =IF(AB30="","",IF(AB30>500,'(Linked) Hazard Risk Number HRN'!$C$37,IF(AB30>50,'(Linked) Hazard Risk Number HRN'!$C$36,IF(AB30>25,'(Linked) Hazard Risk Number HRN'!$C$35,IF(AB30>5,'(Linked) Hazard Risk Number HRN'!$C$34,IF(AB30>0,'(Linked) Hazard Risk Number HRN'!$C$33,"")))))) -> Insignificante | AC28: Detección de presencia: Añadir cortina de luz | AE28: Insignificante: Sin primeros auxilios; rasguño o moretón. | AF28: =IF(ISBLANK(AE28),"",VLOOKUP(AE28,'(Linked) Hazard Risk Number HRN'!$B$6:$C$13,2,FALSE)) -> 0.1 | AG28: =IF(AG30="","",IF(AG30>500,'(Linked) Hazard Risk Number HRN'!$C$37,IF(AG30>50,'(Linked) Hazard Risk Number HRN'!$C$36,IF(AG30>25,'(Linked) Hazard Risk Number HRN'!$C$35,IF(AG30>5,'(Linked) Hazard Risk Number HRN'!$C$34,IF(AG30>0,'(Linked) Hazard Risk Number HRN'!$C$33,"")))))) -> Insignificante
K29: De manera constante o más de una vez cada 15 minutos. | L29: =IF(ISBLANK(K29),"",VLOOKUP(K29,'(Linked) Hazard Risk Number HRN'!$B$16:$C$26,2,FALSE)) -> 5 | N29: Evento de baja o muy baja velocidad ej. <250 mm/s, tiempo para el peligro ≥3s y/o tiempo suficiente para escapar | O29: =IF(ISBLANK(N29),"",VLOOKUP(N29,'(Linked) PLr Probability Factor'!$B$12:$C$14,2,FALSE)) -> A | P29: B | Q29: =COUNTIF((O28:O32), "B") -> 1 | R29: =Q29 -> 1 | S29: =IF(ISBLANK(K29),"",IF(L29<5,"F1","F2")) -> F2 | V29: De manera constante o más de una vez cada 15 minutos. | W29: =IF(ISBLANK(V29),"",VLOOKUP(V29,'(Linked) Hazard Risk Number HRN'!$B$16:$C$26,2,FALSE)) -> 5 | Z29: De manera constante o más de una vez cada 15 minutos. | AA29: =IF(ISBLANK(Z29),"",VLOOKUP(Z29,'(Linked) Hazard Risk Number HRN'!$B$16:$C$26,2,FALSE)) -> 5 | AE29: De manera constante o más de una vez cada 15 minutos. | AF29: =IF(ISBLANK(AE29),"",VLOOKUP(AE29,'(Linked) Hazard Risk Number HRN'!$B$16:$C$26,2,FALSE)) -> 5
K30: Muy probable, es de esperarse | L30: =IF(ISBLANK(K30),"",VLOOKUP(K30,'(Linked) Hazard Risk Number HRN'!$D$6:$E$14,2,FALSE)) -> 10 | M30: =IF(OR(ISBLANK(K28),ISBLANK(K29),ISBLANK(K30),ISBLANK(K31)),"",L28*L29*L30*L31) -> 300 | N30: Imposible | O30: =IF(ISBLANK(N30),"",VLOOKUP(N30,'(Linked) PLr Probability Factor'!$B$17:$C$20,2,FALSE)) -> C | P30: A | Q30: =COUNTIF((O28:O32), "A") -> 3 | R30: =Q30 -> 3 | T30: {=IF(OR(ISBLANK(K28),ISBLANK(K29),ISBLANK(N29),ISBLANK(N30),ISBLANK(N31)),"",INDEX(INDEX('(Linked) PLr Probability Factor'!C$33:$F$44,0,4),MATCH(S28&S29&S32,INDEX('(Linked) PLr Probability Factor'!C$33:$F$44,0,1)&INDEX('(Linked) PLr Probability Factor'!C$33:$F$44,0,2)&INDEX('(Linked) PLr Probability Factor'!C$33:$F$44,0,3),0)))} -> PLe | V30: Casi imposible, posible solo bajo circunstancias extremas | W30: =IF(ISBLANK(V30),"",VLOOKUP(V30,'(Linked) Hazard Risk Number HRN'!$D$6:$E$14,2,FALSE)) -> 0.033 | X30: =IF(OR(ISBLANK(V28),ISBLANK(V29),ISBLANK(V30),ISBLANK(V31)),"",W28*W29*W30*W31) -> 0.0165 | Z30: Casi imposible, posible solo bajo circunstancias extremas | AA30: =IF(ISBLANK(Z30),"",VLOOKUP(Z30,'(Linked) Hazard Risk Number HRN'!$D$6:$E$14,2,FALSE)) -> 0.033 | AB30: =IF(OR(ISBLANK(Z28),ISBLANK(Z29),ISBLANK(Z30),ISBLANK(Z31)),"",AA28*AA29*AA30*AA31) -> 0.0165 | AE30: Casi imposible, posible solo bajo circunstancias extremas | AF30: =IF(ISBLANK(AE30),"",VLOOKUP(AE30,'(Linked) Hazard Risk Number HRN'!$D$6:$E$14,2,FALSE)) -> 0.033 | AG30: =IF(OR(ISBLANK(AE28),ISBLANK(AE29),ISBLANK(AE30),ISBLANK(AE31)),"",AF28*AF29*AF30*AF31) -> 0.0165
K31: 1 a 2 personas | L31: =IF(ISBLANK(K31),"",VLOOKUP(K31,'(Linked) Hazard Risk Number HRN'!$D$17:$E$22,2,FALSE)) -> 1 | N31: Facil reconocimiento del peligro posible en el 50% o mas de los casos | O31: =IF(ISBLANK(N31),"",VLOOKUP(N31,'(Linked) PLr Probability Factor'!$B$23:$C$26,2,FALSE)) -> A | P31: Total | Q31: =SUM(R28:R30) -> 5 | R31: =Q31 -> 5 | V31: 1 a 2 personas | W31: =IF(ISBLANK(V31),"",VLOOKUP(V31,'(Linked) Hazard Risk Number HRN'!$D$17:$E$22,2,FALSE)) -> 1 | Z31: 1 a 2 personas | AA31: =IF(ISBLANK(Z31),"",VLOOKUP(Z31,'(Linked) Hazard Risk Number HRN'!$D$17:$E$22,2,FALSE)) -> 1 | AE31: 1 a 2 personas | AF31: =IF(ISBLANK(AE31),"",VLOOKUP(AE31,'(Linked) Hazard Risk Number HRN'!$D$17:$E$22,2,FALSE)) -> 1
N32: Media a alta complejidad ej. (hold‑to‑run) para el ajuste o configuración de una parte de la máquina. | O32: =IF(ISBLANK(N32),"",VLOOKUP(N32,'(Linked) PLr Probability Factor'!$B$29:$C$32,2,FALSE)) -> B | S32: =IF(OR(ISBLANK(N29),ISBLANK(N30),ISBLANK(N31)),"",IF(R28>0,"P2",IF(AND(R28=0,R29>2),"P2",IF(AND(R28=0,R29=2),"P2",IF(AND(R28=0,AND(R29<2,R30>1)),"P1"," "))))) -> P2
B33: 6 | C33: Mantenimiento preventivo | D33: Sistema de control: ciclo automático/arranque inesperado | H33: X | K33: Mayor: Lesión grave, fractura ósea o cirugía general; incapacidad laboral documentada. Labores restringidas por más de 2 semanas y menos de 6 meses. | L33: =IF(ISBLANK(K33),"",VLOOKUP(K33,'(Linked) Hazard Risk Number HRN'!$B$6:$C$13,2,FALSE)) -> 6 | M33: =IF(M35="","",IF(M35>500,'(Linked) Hazard Risk Number HRN'!$C$37,IF(M35>50,'(Linked) Hazard Risk Number HRN'!$C$36,IF(M35>25,'(Linked) Hazard Risk Number HRN'!$C$35,IF(M35>5,'(Linked) Hazard Risk Number HRN'!$C$34,IF(M35>0,'(Linked) Hazard Risk Number HRN'!$C$33,"")))))) -> Riesgo Alto | N33: Persona calificada | O33: =IF(ISBLANK(N33),"",VLOOKUP(N33,'(Linked) PLr Probability Factor'!$B$7:$C$8,2,FALSE)) -> A | P33: C | Q33: =COUNTIF((O33:O37), "C") -> 1 | R33: =Q33 -> 1 | S33: =IF(ISBLANK(K33),"",IF(L33<2,"S1","S2")) -> S2 | U33: Protección/puerta móvil: Añadir nueva, con Interlocked | V33: Insignificante: Sin primeros auxilios; rasguño o moretón. | W33: =IF(ISBLANK(V33),"",VLOOKUP(V33,'(Linked) Hazard Risk Number HRN'!$B$6:$C$13,2,FALSE)) -> 0.1 | X33: =IF(X35="","",IF(X35>500,'(Linked) Hazard Risk Number HRN'!$C$37,IF(X35>50,'(Linked) Hazard Risk Number HRN'!$C$36,IF(X35>25,'(Linked) Hazard Risk Number HRN'!$C$35,IF(X35>5,'(Linked) Hazard Risk Number HRN'!$C$34,IF(X35>0,'(Linked) Hazard Risk Number HRN'!$C$33,"")))))) -> Insignificante | Y33: Mantenimiento: Procedimiento/SOP/LOTO | Z33: Insignificante: Sin primeros auxilios; rasguño o moretón. | AA33: =IF(ISBLANK(Z33),"",VLOOKUP(Z33,'(Linked) Hazard Risk Number HRN'!$B$6:$C$13,2,FALSE)) -> 0.1 | AB33: =IF(AB35="","",IF(AB35>500,'(Linked) Hazard Risk Number HRN'!$C$37,IF(AB35>50,'(Linked) Hazard Risk Number HRN'!$C$36,IF(AB35>25,'(Linked) Hazard Risk Number HRN'!$C$35,IF(AB35>5,'(Linked) Hazard Risk Number HRN'!$C$34,IF(AB35>0,'(Linked) Hazard Risk Number HRN'!$C$33,"")))))) -> Insignificante | AC33: Detección de presencia: Añadir cortina de luz | AE33: Insignificante: Sin primeros auxilios; rasguño o moretón. | AF33: =IF(ISBLANK(AE33),"",VLOOKUP(AE33,'(Linked) Hazard Risk Number HRN'!$B$6:$C$13,2,FALSE)) -> 0.1 | AG33: =IF(AG35="","",IF(AG35>500,'(Linked) Hazard Risk Number HRN'!$C$37,IF(AG35>50,'(Linked) Hazard Risk Number HRN'!$C$36,IF(AG35>25,'(Linked) Hazard Risk Number HRN'!$C$35,IF(AG35>5,'(Linked) Hazard Risk Number HRN'!$C$34,IF(AG35>0,'(Linked) Hazard Risk Number HRN'!$C$33,"")))))) -> Insignificante
K34: Semanal | L34: =IF(ISBLANK(K34),"",VLOOKUP(K34,'(Linked) Hazard Risk Number HRN'!$B$16:$C$26,2,FALSE)) -> 1.5 | N34: Evento de baja o muy baja velocidad ej. <250 mm/s, tiempo para el peligro ≥3s y/o tiempo suficiente para escapar | O34: =IF(ISBLANK(N34),"",VLOOKUP(N34,'(Linked) PLr Probability Factor'!$B$12:$C$14,2,FALSE)) -> A | P34: B | Q34: =COUNTIF((O33:O37), "B") -> 1 | R34: =Q34 -> 1 | S34: =IF(ISBLANK(K34),"",IF(L34<5,"F1","F2")) -> F1 | V34: Semanal | W34: =IF(ISBLANK(V34),"",VLOOKUP(V34,'(Linked) Hazard Risk Number HRN'!$B$16:$C$26,2,FALSE)) -> 1.5 | Z34: Semanal | AA34: =IF(ISBLANK(Z34),"",VLOOKUP(Z34,'(Linked) Hazard Risk Number HRN'!$B$16:$C$26,2,FALSE)) -> 1.5 | AE34: Semanal | AF34: =IF(ISBLANK(AE34),"",VLOOKUP(AE34,'(Linked) Hazard Risk Number HRN'!$B$16:$C$26,2,FALSE)) -> 1.5
K35: Muy probable, es de esperarse | L35: =IF(ISBLANK(K35),"",VLOOKUP(K35,'(Linked) Hazard Risk Number HRN'!$D$6:$E$14,2,FALSE)) -> 10 | M35: =IF(OR(ISBLANK(K33),ISBLANK(K34),ISBLANK(K35),ISBLANK(K36)),"",L33*L34*L35*L36) -> 90 | N35: Imposible | O35: =IF(ISBLANK(N35),"",VLOOKUP(N35,'(Linked) PLr Probability Factor'!$B$17:$C$20,2,FALSE)) -> C | P35: A | Q35: =COUNTIF((O33:O37), "A") -> 3 | R35: =Q35 -> 3 | T35: {=IF(OR(ISBLANK(K33),ISBLANK(K34),ISBLANK(N34),ISBLANK(N35),ISBLANK(N36)),"",INDEX(INDEX('(Linked) PLr Probability Factor'!C$33:$F$44,0,4),MATCH(S33&S34&S37,INDEX('(Linked) PLr Probability Factor'!C$33:$F$44,0,1)&INDEX('(Linked) PLr Probability Factor'!C$33:$F$44,0,2)&INDEX('(Linked) PLr Probability Factor'!C$33:$F$44,0,3),0)))} -> PLd | V35: Casi imposible, posible solo bajo circunstancias extremas | W35: =IF(ISBLANK(V35),"",VLOOKUP(V35,'(Linked) Hazard Risk Number HRN'!$D$6:$E$14,2,FALSE)) -> 0.033 | X35: =IF(OR(ISBLANK(V33),ISBLANK(V34),ISBLANK(V35),ISBLANK(V36)),"",W33*W34*W35*W36) -> 0.00495 | Z35: Casi imposible, posible solo bajo circunstancias extremas | AA35: =IF(ISBLANK(Z35),"",VLOOKUP(Z35,'(Linked) Hazard Risk Number HRN'!$D$6:$E$14,2,FALSE)) -> 0.033 | AB35: =IF(OR(ISBLANK(Z33),ISBLANK(Z34),ISBLANK(Z35),ISBLANK(Z36)),"",AA33*AA34*AA35*AA36) -> 0.00495 | AE35: Casi imposible, posible solo bajo circunstancias extremas | AF35: =IF(ISBLANK(AE35),"",VLOOKUP(AE35,'(Linked) Hazard Risk Number HRN'!$D$6:$E$14,2,FALSE)) -> 0.033 | AG35: =IF(OR(ISBLANK(AE33),ISBLANK(AE34),ISBLANK(AE35),ISBLANK(AE36)),"",AF33*AF34*AF35*AF36) -> 0.00495
K36: 1 a 2 personas | L36: =IF(ISBLANK(K36),"",VLOOKUP(K36,'(Linked) Hazard Risk Number HRN'!$D$17:$E$22,2,FALSE)) -> 1 | N36: Facil reconocimiento del peligro posible en el 50% o mas de los casos | O36: =IF(ISBLANK(N36),"",VLOOKUP(N36,'(Linked) PLr Probability Factor'!$B$23:$C$26,2,FALSE)) -> A | P36: Total | Q36: =SUM(R33:R35) -> 5 | R36: =Q36 -> 5 | V36: 1 a 2 personas | W36: =IF(ISBLANK(V36),"",VLOOKUP(V36,'(Linked) Hazard Risk Number HRN'!$D$17:$E$22,2,FALSE)) -> 1 | Z36: 1 a 2 personas | AA36: =IF(ISBLANK(Z36),"",VLOOKUP(Z36,'(Linked) Hazard Risk Number HRN'!$D$17:$E$22,2,FALSE)) -> 1 | AE36: 1 a 2 personas | AF36: =IF(ISBLANK(AE36),"",VLOOKUP(AE36,'(Linked) Hazard Risk Number HRN'!$D$17:$E$22,2,FALSE)) -> 1
N37: Media a alta complejidad ej. (hold‑to‑run) para el ajuste o configuración de una parte de la máquina. | O37: =IF(ISBLANK(N37),"",VLOOKUP(N37,'(Linked) PLr Probability Factor'!$B$29:$C$32,2,FALSE)) -> B | S37: =IF(OR(ISBLANK(N34),ISBLANK(N35),ISBLANK(N36)),"",IF(R33>0,"P2",IF(AND(R33=0,R34>2),"P2",IF(AND(R33=0,R34=2),"P2",IF(AND(R33=0,AND(R34<2,R35>1)),"P1"," "))))) -> P2
B38: 7 | C38: Mantenimiento correctivo/Solución de problemas | D38: Sistema de control: ciclo automático/arranque inesperado | H38: X | K38: Mayor: Lesión grave, fractura ósea o cirugía general; incapacidad laboral documentada. Labores restringidas por más de 2 semanas y menos de 6 meses. | L38: =IF(ISBLANK(K38),"",VLOOKUP(K38,'(Linked) Hazard Risk Number HRN'!$B$6:$C$13,2,FALSE)) -> 6 | M38: =IF(M40="","",IF(M40>500,'(Linked) Hazard Risk Number HRN'!$C$37,IF(M40>50,'(Linked) Hazard Risk Number HRN'!$C$36,IF(M40>25,'(Linked) Hazard Risk Number HRN'!$C$35,IF(M40>5,'(Linked) Hazard Risk Number HRN'!$C$34,IF(M40>0,'(Linked) Hazard Risk Number HRN'!$C$33,"")))))) -> Riesgo Alto | N38: Persona calificada | O38: =IF(ISBLANK(N38),"",VLOOKUP(N38,'(Linked) PLr Probability Factor'!$B$7:$C$8,2,FALSE)) -> A | P38: C | Q38: =COUNTIF((O38:O42), "C") -> 2 | R38: =Q38 -> 2 | S38: =IF(ISBLANK(K38),"",IF(L38<2,"S1","S2")) -> S2 | U38: Protección/puerta móvil: Añadir nueva, con Interlocked | V38: Insignificante: Sin primeros auxilios; rasguño o moretón. | W38: =IF(ISBLANK(V38),"",VLOOKUP(V38,'(Linked) Hazard Risk Number HRN'!$B$6:$C$13,2,FALSE)) -> 0.1 | X38: =IF(X40="","",IF(X40>500,'(Linked) Hazard Risk Number HRN'!$C$37,IF(X40>50,'(Linked) Hazard Risk Number HRN'!$C$36,IF(X40>25,'(Linked) Hazard Risk Number HRN'!$C$35,IF(X40>5,'(Linked) Hazard Risk Number HRN'!$C$34,IF(X40>0,'(Linked) Hazard Risk Number HRN'!$C$33,"")))))) -> Insignificante | Y38: Mantenimiento: Procedimiento/SOP/LOTO | Z38: Insignificante: Sin primeros auxilios; rasguño o moretón. | AA38: =IF(ISBLANK(Z38),"",VLOOKUP(Z38,'(Linked) Hazard Risk Number HRN'!$B$6:$C$13,2,FALSE)) -> 0.1 | AB38: =IF(AB40="","",IF(AB40>500,'(Linked) Hazard Risk Number HRN'!$C$37,IF(AB40>50,'(Linked) Hazard Risk Number HRN'!$C$36,IF(AB40>25,'(Linked) Hazard Risk Number HRN'!$C$35,IF(AB40>5,'(Linked) Hazard Risk Number HRN'!$C$34,IF(AB40>0,'(Linked) Hazard Risk Number HRN'!$C$33,"")))))) -> Insignificante | AC38: Protección/puerta móvil: Añadir nueva, con Interlocked | AE38: Insignificante: Sin primeros auxilios; rasguño o moretón. | AF38: =IF(ISBLANK(AE38),"",VLOOKUP(AE38,'(Linked) Hazard Risk Number HRN'!$B$6:$C$13,2,FALSE)) -> 0.1 | AG38: =IF(AG40="","",IF(AG40>500,'(Linked) Hazard Risk Number HRN'!$C$37,IF(AG40>50,'(Linked) Hazard Risk Number HRN'!$C$36,IF(AG40>25,'(Linked) Hazard Risk Number HRN'!$C$35,IF(AG40>5,'(Linked) Hazard Risk Number HRN'!$C$34,IF(AG40>0,'(Linked) Hazard Risk Number HRN'!$C$33,"")))))) -> Insignificante
K39: Una a varias veces cada 12 horas — Duración total de las tareas ≤ 36 minutos. | L39: =IF(ISBLANK(K39),"",VLOOKUP(K39,'(Linked) Hazard Risk Number HRN'!$B$16:$C$26,2,FALSE)) -> 2.5 | N39: Evento de alta velocidad ej. > 1000 mm/s, tiempo para el peligro <1s y/o Tiempo limitado para escapar | O39: =IF(ISBLANK(N39),"",VLOOKUP(N39,'(Linked) PLr Probability Factor'!$B$12:$C$14,2,FALSE)) -> C | P39: B | Q39: =COUNTIF((O38:O42), "B") -> 1 | R39: =Q39 -> 1 | S39: =IF(ISBLANK(K39),"",IF(L39<5,"F1","F2")) -> F1 | V39: Una a varias veces cada 12 horas — Duración total de las tareas ≤ 36 minutos. | W39: =IF(ISBLANK(V39),"",VLOOKUP(V39,'(Linked) Hazard Risk Number HRN'!$B$16:$C$26,2,FALSE)) -> 2.5 | Z39: Una a varias veces cada 12 horas — Duración total de las tareas ≤ 36 minutos. | AA39: =IF(ISBLANK(Z39),"",VLOOKUP(Z39,'(Linked) Hazard Risk Number HRN'!$B$16:$C$26,2,FALSE)) -> 2.5 | AE39: Una a varias veces cada 12 horas — Duración total de las tareas ≤ 36 minutos. | AF39: =IF(ISBLANK(AE39),"",VLOOKUP(AE39,'(Linked) Hazard Risk Number HRN'!$B$16:$C$26,2,FALSE)) -> 2.5
K40: Muy probable, es de esperarse | L40: =IF(ISBLANK(K40),"",VLOOKUP(K40,'(Linked) Hazard Risk Number HRN'!$D$6:$E$14,2,FALSE)) -> 10 | M40: =IF(OR(ISBLANK(K38),ISBLANK(K39),ISBLANK(K40),ISBLANK(K41)),"",L38*L39*L40*L41) -> 150 | N40: Imposible | O40: =IF(ISBLANK(N40),"",VLOOKUP(N40,'(Linked) PLr Probability Factor'!$B$17:$C$20,2,FALSE)) -> C | P40: A | Q40: =COUNTIF((O38:O42), "A") -> 2 | R40: =Q40 -> 2 | T40: {=IF(OR(ISBLANK(K38),ISBLANK(K39),ISBLANK(N39),ISBLANK(N40),ISBLANK(N41)),"",INDEX(INDEX('(Linked) PLr Probability Factor'!C$33:$F$44,0,4),MATCH(S38&S39&S42,INDEX('(Linked) PLr Probability Factor'!C$33:$F$44,0,1)&INDEX('(Linked) PLr Probability Factor'!C$33:$F$44,0,2)&INDEX('(Linked) PLr Probability Factor'!C$33:$F$44,0,3),0)))} -> PLd | V40: Casi imposible, posible solo bajo circunstancias extremas | W40: =IF(ISBLANK(V40),"",VLOOKUP(V40,'(Linked) Hazard Risk Number HRN'!$D$6:$E$14,2,FALSE)) -> 0.033 | X40: =IF(OR(ISBLANK(V38),ISBLANK(V39),ISBLANK(V40),ISBLANK(V41)),"",W38*W39*W40*W41) -> 0.00825 | Z40: Casi imposible, posible solo bajo circunstancias extremas | AA40: =IF(ISBLANK(Z40),"",VLOOKUP(Z40,'(Linked) Hazard Risk Number HRN'!$D$6:$E$14,2,FALSE)) -> 0.033 | AB40: =IF(OR(ISBLANK(Z38),ISBLANK(Z39),ISBLANK(Z40),ISBLANK(Z41)),"",AA38*AA39*AA40*AA41) -> 0.00825 | AE40: Casi imposible, posible solo bajo circunstancias extremas | AF40: =IF(ISBLANK(AE40),"",VLOOKUP(AE40,'(Linked) Hazard Risk Number HRN'!$D$6:$E$14,2,FALSE)) -> 0.033 | AG40: =IF(OR(ISBLANK(AE38),ISBLANK(AE39),ISBLANK(AE40),ISBLANK(AE41)),"",AF38*AF39*AF40*AF41) -> 0.00825
K41: 1 a 2 personas | L41: =IF(ISBLANK(K41),"",VLOOKUP(K41,'(Linked) Hazard Risk Number HRN'!$D$17:$E$22,2,FALSE)) -> 1 | N41: Facil reconocimiento del peligro posible en el 50% o mas de los casos | O41: =IF(ISBLANK(N41),"",VLOOKUP(N41,'(Linked) PLr Probability Factor'!$B$23:$C$26,2,FALSE)) -> A | P41: Total | Q41: =SUM(R38:R40) -> 5 | R41: =Q41 -> 5 | V41: 1 a 2 personas | W41: =IF(ISBLANK(V41),"",VLOOKUP(V41,'(Linked) Hazard Risk Number HRN'!$D$17:$E$22,2,FALSE)) -> 1 | Z41: 1 a 2 personas | AA41: =IF(ISBLANK(Z41),"",VLOOKUP(Z41,'(Linked) Hazard Risk Number HRN'!$D$17:$E$22,2,FALSE)) -> 1 | AE41: 1 a 2 personas | AF41: =IF(ISBLANK(AE41),"",VLOOKUP(AE41,'(Linked) Hazard Risk Number HRN'!$D$17:$E$22,2,FALSE)) -> 1
N42: Media a alta complejidad ej. (hold‑to‑run) para el ajuste o configuración de una parte de la máquina. | O42: =IF(ISBLANK(N42),"",VLOOKUP(N42,'(Linked) PLr Probability Factor'!$B$29:$C$32,2,FALSE)) -> B | S42: =IF(OR(ISBLANK(N39),ISBLANK(N40),ISBLANK(N41)),"",IF(R38>0,"P2",IF(AND(R38=0,R39>2),"P2",IF(AND(R38=0,R39=2),"P2",IF(AND(R38=0,AND(R39<2,R40>1)),"P1"," "))))) -> P2
...

Sheet Resumen
H1: EVALUACIÓN INICIAL - SIN SALVAGUARDAS / SIN PROTECCIÓN | J1: PLr | K1: REEVALUACIÓN CON LAS SALVAGUARDAS EXISTENTES | N1: CONTROLES PROPUESTOS PARA REDUCIR EL RIESGO A UN NIVEL ACEPTABLE | Q1: CONTROLES REALES IMPLEMENTADOS PARA REDUCIR EL RIESGO A UN NIVEL ACEPTABLE
A2: PELIGRO # | B2: Condición de Uso (Tarea) | C2: Peligro(s) / Modo de fallo | D2: Operator | E2: Mantenimiento | F2: Contractors | G2: Otros | H2: Antes de HRN | I2: Antes del nivel de riesgo | J2: ISO 13849 PLr | K2: Mitigación actual | L2: HRN actual | M2: Nivel de riesgo actual | N2: Mitigación propuesta | O2: HRN propuesta | P2: Nivel de riesgo propuesto | Q2: Implemented Mitigation | R2: Implemented HRN | S2: Implemented Risk Level
A3: =IF(ISBLANK('MRA Evaluacion completa'!B8),"",'MRA Evaluacion completa'!B8) -> 1 | B3: o | C3: =IF(ISBLANK('MRA Evaluacion completa'!D8),"",'MRA Evaluacion completa'!D8) -> Mecánica: transmisión; pinchazo/aplastamiento/enredamiento. | D3: =IF(ISBLANK('MRA Evaluacion completa'!G8),"",'MRA Evaluacion completa'!G8) -> X | E3: =IF(ISBLANK('MRA Evaluacion completa'!H8),"",'MRA Evaluacion completa'!H8) -> X | F3: =IF(ISBLANK('MRA Evaluacion completa'!I8),"",'MRA Evaluacion completa'!I8) | G3: =IF(ISBLANK('MRA Evaluacion completa'!J8),"",'MRA Evaluacion completa'!J8) | H3: ='MRA Evaluacion completa'!$M$10 -> 200 | I3: ='MRA Evaluacion completa'!$M$8 -> Riesgo Alto | J3: ='MRA Evaluacion completa'!$T$10 -> PLd | K3: =IF(ISBLANK('MRA Evaluacion completa'!$U$8),"",'MRA Evaluacion completa'!$U$8) -> Detección de presencia: Añadir cortina de luz | L3: ='MRA Evaluacion completa'!$X$10 -> 0.0165 | M3: ='MRA Evaluacion completa'!$X$8 -> Insignificante | N3: =IF(ISBLANK('MRA Evaluacion completa'!$Y$8),"",'MRA Evaluacion completa'!$Y$8) -> Mantenimiento: Procedimiento/SOP/LOTO | O3: ='MRA Evaluacion completa'!$AB$10 -> 0.00495 | P3: ='MRA Evaluacion completa'!$AB$8 -> Insignificante | Q3: =IF(ISBLANK('MRA Evaluacion completa'!$AC$8),"",'MRA Evaluacion completa'!$AC$8) -> Detección de presencia: Añadir cortina de luz | R3: ='MRA Evaluacion completa'!$AG$10 -> 0.0165 | S3: =IF(ISBLANK('MRA Evaluacion completa'!$AG$8),"",'MRA Evaluacion completa'!$AG$8) -> Insignificante
