Workbook
Name abcdefg: #REF!
Name Cavities: #REF!
Name Choose: #REF!
Name CONSTANTES: #REF!
Name CONSTANTS: #REF!
Name decoupled: #REF!
Name decoupled2: #REF!
Name degrees: #REF!
Name Document: #REF!
Name DPH: '(Linked) Hazard Risk Number HRN'!$B$6:$C$13
Name drytime: #REF!
Name eject: #REF!
Name EJECTPATT: #REF!
Name ejectpattern: #REF!
Name ejtpat: #REF!
Name fabulous: #REF!
Name fasdfsdfsd: #REF!
Name FE: '(Linked) Hazard Risk Number HRN'!$B$16:$C$26
Name Flow_transfer_mod: #REF!
Name FlowRatePlastic: #REF!
Name flowstudy: #REF!
Name Force: #REF!
Name formula: #REF!
Name g: #REF!
Name l: #REF!
Name Linear: #REF!
Name LO: '(Linked) Hazard Risk Number HRN'!$D$6:$E$14
Name machine: #REF!
Name MachineType: #REF!
Name Mfg: #REF!
Name Moldtype: #REF!
Name NP: '(Linked) Hazard Risk Number HRN'!$D$17:$E$22
Name OLE_LINK3: 'Portada del documento JDOC'!#REF!
Name PA: '(Linked) Hazard Risk Number HRN'!$D$25:$E$27
Name Piezo: #REF!
Name PLr: #REF!
Name position: #REF!
Name Press.: #REF!
Name presses: #REF!
Name Pressure: #REF!
Name Process: #REF!
Name process3: #REF!
Name processeng: #REF!
Name Recovery: #REF!
Name Resins: #REF!
Name Revision: #REF!
Name scale: #REF!
Name SDFASDFS: #REF!
Name sdsdgfasdg: #REF!
Name Security: #REF!
Name SPECHEAT: #REF!
Name Speed: #REF!
Name Table_Press: #REF!
Name tctype: #REF!
Name Temps: #REF!
Name Test: #REF!
Name therm2: #REF!
Name THERMAL: #REF!
Name Time: #REF!
Name Title: #REF!

Sheet Portada del documento JDOC
C1: 16-HS80-8000-00020 | E1: Revision
E2: B
C3: Evaluación de riesgos de maquinaria | E3: Categoría de documentación
E4: Obligatorio
A5: Aprobaciones | D5: Designación
A6: Chad McClimans | D6: Global Environmental Health & Safety Director
A7: Conor Kenny | D7: Sr Director Global Automation
A8: Detalles de la revisión (Nota: Consulte la información del documento del sistema para conocer la fecha de lanzamiento)
A9: Revision | B9: Detalles del cambio | E9: Autor
A10: A | B10: Lanzamiento inicial | E10: Guajana Skyers
A11: B | B11: Revisado al nuevo formulario de evaluación de riesgos de la máquina con hojas de apoyo. | E11: John Tebbe
A12: 1.0 Proposito
A13: El objetivo de la herramienta de evaluación de riesgos de máquinas (MRA) es respaldar la actividad de evaluación de riesgos proporcionando un método de evaluación coherente y completo. Una evaluación completa y conforme, que cumpla con las expectativas, garantizará que solo se utilicen equipos seguros en las operaciones antes de que cualquier equipo se libere en la célula de trabajo para la validación/calificación del proceso y/o la producción comercial. El proceso MRA pone a prueba el equipo evaluando los riesgos de seguridad/ergonomía que están presentes en el equipo durante su funcionamiento. Un Los sitios que ya cuentan con evaluaciones de riesgos de maquinaria deben realizar un análisis de deficiencias y subsanarlas. El objetivo es reducir el riesgo empresarial, proteger la salud y la seguridad de los empleados de Jabil, así como cumplir con los requisitos normativos y de los clientes.
A14: 2.0 Alcance
A15: Todos los sitios a nivel mundial que requieren un sistema de evaluación de riesgos de maquinaria según lo definido por la Norma de Seguridad de Maquinaria SE-ES20-00004. La mejor práctica para la evaluación inicial comienza durante la revisión del diseño, se reevalúa durante la construcción/prueba de aceptación de fábrica (FAT) y se reevalúa en la prueba de aceptación en el sitio (SAT) para nuevas construcciones, ya que se trata de un documento vivo.
A16: 3.0 Referencias
A17: Este documento debe utilizarse junto con los siguientes procedimientos:
A18: Numero de documento | C18: Document Title
A19: SE-ES20-00004 | C19: Estandar de seguridad en maquinaria
A20: 16-HS20-8000-00010 | C20: Procedimiento de seguridad en maquinaria
A21: 00-AT20-00001 | C21: Estandar de Introducción a la automatización de ensambles
A22: 4.0 Instrucciones
A23: 4.1 Revise la norma de seguridad de máquinas SE-ES20-00004 para conocer y comprender los requisitos mínimos de seguridad de máquinas de Jabil antes de seguir las instrucciones que se indican a continuación.
A24: Lea atentamente las instrucciones que figuran a continuación, así como las pestañas de referencia adicionales incluidas en el libro de trabajo. Las dos pestañas que deben utilizarse se describen en las secciones 4.4 y 4.5. Las secciones 4.7 a 4.9 son pestañas adicionales de apoyo para el análisis de datos, la presentación de informes y el seguimiento de las medidas destinadas a reducir los niveles de peligro residual que quedan tras la evaluación inicial.
A25: 4.1 Se espera que los centros utilicen este formulario MRA para documentar su evaluación. El MRA puede ser realizado por el contratista o por un tercero autorizado. Los centros que dispongan de un formulario o software equivalente que se considere que cumple o supera estos requisitos pueden solicitar su sustitución con la aprobación por escrito de los responsables de la aprobación de la plantilla anterior o de la persona designada.
A26: 4.2 Aunque los sitios web ofrecen una gran flexibilidad para añadir contenido y criterios para la evaluación de riesgos de la maquinaria, NO ELIMINE ni modifique ninguna fórmula, ponderación de factores o criterio del Índice de Riesgo de Peligro (HRN). El sitio web deberá revisar todos los peligros asociados a la máquina y las tareas relacionadas con la interacción con el equipo.
A27: 4.3. Se recomienda que el equipo de evaluación esté compuesto por entre 3 y 5 personas. Se debe calcular la media de cada aportación y votar si es necesario para acordar el HRN resultante, por lo que se recomienda que el número de miembros sea impar. Lo ideal es que los miembros del equipo que participen estén familiarizados con la tarea y la operación que se evalúa en su área de especialización. La MRA puede ser realizada por un contratista o un tercero autorizado, dependiendo de la complejidad del proyecto y/o de la disponibilidad del equipo competente en el lugar. El equipo puede cambiar en función de la condición de uso que se evalúe. A continuación se indican los requisitos mínimos para cada condición de uso o tarea de evaluación. - Operaciones normales: mínimo de (Medio Ambiente, Salud y Seguridad (EHS), Procesos/Automatización, Operaciones. - Manipulación de materiales: mínimo de EHS, Procesos/Automatización, Operaciones o tareas específicas de almacén. - Recuperación de fallos: mínimo de EHS, proceso/automatización, operaciones o tareas específicas de mantenimiento. - Mantenimiento correctivo/resolución de problemas: mínimo de EHS, proceso/automatización, operaciones o tareas específicas de mantenimiento. - Mantenimiento preventivo: mínimo EHS, procesos/automatización, mantenimiento/mecánica. - Modo de parada de emergencia/recuperación: mínimo EHS, procesos/automatización, operaciones o tareas específicas de mantenimiento. - Modo manual: mínimo EHS, procesos/automatización, mantenimiento/mecánica u operaciones específicas. - Arranque/apagado: mínimo EHS, proceso/automatización, mantenimiento/mecánica u operaciones específicas. - Bloqueo/prueba (LOTO): mínimo EHS, proceso/automatización, mantenimiento/mecánica. - Ajustes mecánicos: Mínimo EHS, proceso/automatización, mantenimiento/mecánica u operaciones específicas. - Configuración/cambio: Mínimo EHS, proceso/automatización, mantenimiento/mecánica u operaciones específicas.
A28: 4.4 Comience aquí_Cubierta_Pestaña de revisión
A29: 4.4A Introduzca el cliente, la ubicación del sitio, el número de proyecto/máquina, la fecha y el responsable en la parte superior.
A30: 4.4B Introduzca la versión, la fecha, el autor de la modificación y la descripción en la tabla del historial de revisiones de la evaluación. La primera revisión será la versión inicial. La evaluación es un documento vivo y el historial de revisiones se utiliza para documentar las actualizaciones posteriores a la evaluación inicial.
A31: 4.5 Pestaña de evaluación completa de MRA
A32: 4.5A Número de serie de entrada, fecha de fabricación, descripción de la máquina/línea o enfoque de la evaluación, ubicación de la planta del edificio en la parte superior de la evaluación.
A33: 4.5B Condiciones de uso (tarea) Este campo se puede rellenar manualmente o utilizar el menú desplegable para equipos más sencillos (personalizable en la pestaña Referencias del menú desplegable (vinculado)). Se recomienda incluir aquí suficiente información para que otras personas que no participen en la evaluación puedan seguirla con claridad. Ejemplo: Operaciones normales: Estación 01, carga de la carcasa, recogida y colocación. Utilice 4.3 como condiciones mínimas para evaluar, así como tener en cuenta todos los modos para los que está programado el equipo (automático, semiautomático, paso a paso, manual, jog). Pruebe físicamente el equipo, no se limite a comprobar que hay una cortina de luz y dar por sentado que los controles están en su sitio, sino que verifique que no se puede burlar ni dar acceso a peligros en la condición que se está evaluando.
... A38: 4.5G El nivel de riesgo y el índice de riesgo (HRN) se completarán automáticamente una vez que se hayan ponderado los cuatro elementos. El HRN inicial será alto, ya que se evalúa sin medidas de seguridad. El objetivo del cálculo del HRN es identificar los riesgos medios, altos e inaceptables que no son admisibles y determinar las medidas esenciales de reducción del riesgo para alcanzar un nivel de HRN aceptable. Esto se puede lograr reduciendo la probabilidad de sufrir daños o eliminando los peligros, la frecuencia o la exposición mediante un rediseño, ya sea reduciendo por separado o simultáneamente cada uno de los 4 elementos que determinan el riesgo asociado. Para obtener más información, consulte la pestaña de referencia del nivel de riesgo HRN (Ref.). A continuación se describen las expectativas mínimas de Jabil para un HRN aceptable y las acciones mínimas para un HRN medio/alto/inaceptable:
B39: 0 - 5 | C39: Riesgo insignificante | D39: Riesgo aceptable. No se requiere ninguna acción. Los usuarios finales deben seguir el manual del usuario, el procedimiento operativo estándar (SOP), las instrucciones de trabajo (WI), las ayudas visuales (VA), las señales de seguridad (pictogramas), la formación básica y el equipo de protección individual (EPI).
B40: >5 - 25 | C40: Riesgo bajo
B41: >25 - 50 | C41: Riesgo Medio | D41: Riesgo inaceptable. El centro deberá implementar medidas de control esenciales (evaluar soluciones de control de ingeniería sólidas, salvaguardias, etc., frente a medidas administrativas o EPI).
B42: >50 - 500 | C42: Riesgo Alto
B43: > 500 | C43: Riesgo inaceptable | D43: No es aceptable bajo ninguna circunstancia. La máquina no debe ponerse en funcionamiento. El sitio debe considerar un cambio en el diseño para que la máquina sea intrínsecamente segura y, a continuación, implementar las medidas de control esenciales.
A44: 4.5H IS0 13849-1 Clasificación del nivel de rendimiento (PLr). Esta sección puede dejarse en blanco para evaluaciones generales a nivel de sitio que NO construyan, integren, actualicen ni modifiquen equipos. Esta sección debe utilizarse con fabricantes de máquinas internos o externos, integradores (que conectan máquinas «listas para usar» y/o las unen entre sí como una línea o un sistema), actualizaciones o modificaciones. Se utiliza en la fase de diseño de la maquinaria, integridad máquina a máquina: el diseñador, integrador o ingeniero de procesos debe identificar el nivel de rendimiento requerido (PLr) de conformidad con la parte relacionada con la seguridad de los sistemas de control de la norma ISO 13849-1. Para ello, determine la probabilidad (P) según la sección de la norma ISO 13849 respondiendo a las 5 preguntas del menú desplegable. Debe completar el grado de daño posible (DPH) y la frecuencia de exposición a los peligros (FE) de la sección HRN de la evaluación inicial de riesgos para rellenar la gravedad (S) y la frecuencia (F). El nivel de rendimiento requerido (PLr) se rellenará automáticamente una vez que se hayan respondido las 5 preguntas. En función de los resultados, el PLr se rellenará automáticamente. Para obtener más información, consulte la pestaña de referencia del nivel de rendimiento PLr (Ref.).
...

Sheet Empezar aquí_Portada_Revisión
B1: Cliente | C1: John Deere | H1: Ubicación | I1: Jabil | L1: Fecha | M1: 22/09/2026
B2: Celula/ Numero de maquina: | C2: KASALIS PIXID 500 (embotellamiento compartido: SCORPION, MOOSE, GECKO, INFURROW) | L2: Responsable: | M2: EHS / Automation
B4: Evaluación de riesgos de máquinas mediante el sistema de clasificación de peligros por números
B6: Tabla de revisión
B7: Version | C7: Fecha | E7: Modificado por | I7: Descripción de los cambios

Sheet MRA Full Assessment
B2: Nombre de máquina /Número | D2: =IF(ISBLANK('Empezar aquí_Portada_Revisión'!C2),"",'Empezar aquí_Portada_Revisión'!C2) | E2: Serial #: | F2: - | G2: Fecha MFG: | I2: - | K2: Ubicación: | L2: =IF(ISBLANK('Empezar aquí_Portada_Revisión'!I1),"",'Empezar aquí_Portada_Revisión'!I1) | Y2: Fecha: | Z2: ='Empezar aquí_Portada_Revisión'!$M$1 -> 0
B3: Descripción de la máquina: | D3: - | K3: Ubicación del edificio/planta: | L3: - | Y3: Por: | Z3: ='Empezar aquí_Portada_Revisión'!$M$2 -> 0
B5: PELIGRO # | C5: Condición de uso (Tarea) | D5: Peligro(s) / Modo de fallo | E5: Imágenes | G5: Personas en riesgo | K5: EVALUACIÓN INICIAL - SIN SALVAGUARDAS / SIN PROTECCIÓN | N5: ISO 13849-1:2023 Evaluación inicial de HRN: DPH y FE rellenan automáticamente S y F | U5: CONTROLES PROPUESTOS PARA REDUCIR EL RIESGO A UN NIVEL ACEPTABLE | Y5: CONTROLES PROPUESTOS PARA REDUCIR EL RIESGO A UN NIVEL ACEPTABLE | AC5: CONTROLES REALES IMPLEMENTADOS PARA REDUCIR EL RIESGO A UN NIVEL ACEPTABLE
G6: Operador | H6: Mantenimiento | I6: Contratistas | J6: Otros | K6: Gravedad Frecuencia Verosimilitud Número de personas | L6: DPH FE LO NP | M6: Nivel de riesgo HRN | U6: Medida(s) de control ¡No puedes usar la evaluación de riesgos para reducir el grado de protección que exigen los estándares! | V6: Gravedad Frecuencia Verosimilitud Número de personas | W6: DPH FE LO NP | X6: Nivel de riesgo (HRN) | Y6: Medida(s) de control ¡No puedes usar la evaluación de riesgos para reducir el grado de protección que exigen los estándares! | Z6: Gravedad Frecuencia Verosimilitud Número de personas | AA6: DPH FE LO NP | AB6: Nivel de riesgo (HRN) | AC6: Medida(s) de control ¡No puedes usar la evaluación de riesgos para reducir el grado de protección que exigen los estándares! | AD6: Imagen | AE6: Gravedad Frecuencia Verosimilitud Número de personas | AF6: DPH FE LO NP | AG6: Nivel de riesgo (HRN)
E7: Imagen 1 | F7: Imagen 2 | N7: Determine Probability P 13849-1 Avoidance | O7: Factor según la Tabla A.1 ISO 13849 estándar | P7: Count A-C from Factor table HIDDEN CELLS | S7: S F P | T7: PLr
B8: 1 | C8: Operación normal | D8: Mecánico: ciclo automático/arranque repentino | G8: X | K8: Moderate: Significant medical attention (severe laceration), physical therapy (restricted duties <2 weeks) | L8: =IF(ISBLANK(K8),"",VLOOKUP(K8,'(Linked) Hazard Risk Number HRN'!$B$6:$C$13,2,FALSE)) | M8: =IF(M10="","",IF(M10>500,'(Linked) Hazard Risk Number HRN'!$C$37,IF(M10>50,'(Linked) Hazard Risk Number HRN'!$C$36,IF(M10>25,'(Linked) Hazard Risk Number HRN'!$C$35,IF(M10>5,'(Linked) Hazard Risk Number HRN'!$C$34,IF(M10>0,'(Linked) Hazard Risk Number HRN'!$C$33,"")))))) | N8: Unskilled person | O8: =IF(ISBLANK(N8),"",VLOOKUP(N8,'(Linked) PLr Probability Factor'!$B$7:$C$8,2,FALSE)) | P8: C | Q8: =COUNTIF((O8:O12), "C") -> 0 | R8: =Q8 -> 0 | S8: =IF(ISBLANK(K8),"",IF(L8<2,"S1","S2")) | U8: Detección de presencia: Añadir cortina de luz | V8: Very Minor: Basic first aid (small cut, swelling) (adhesive bandage, ice pack, non-rigid supports) | W8: =IF(ISBLANK(V8),"",VLOOKUP(V8,'(Linked) Hazard Risk Number HRN'!$B$6:$C$13,2,FALSE)) | X8: =IF(X10="","",IF(X10>500,'(Linked) Hazard Risk Number HRN'!$C$37,IF(X10>50,'(Linked) Hazard Risk Number HRN'!$C$36,IF(X10>25,'(Linked) Hazard Risk Number HRN'!$C$35,IF(X10>5,'(Linked) Hazard Risk Number HRN'!$C$34,IF(X10>0,'(Linked) Hazard Risk Number HRN'!$C$33,"")))))) | Y8: Procedimiento / Implementación de SOP | Z8: Very Minor: Basic first aid (small cut, swelling) (adhesive bandage, ice pack, non-rigid supports) | AA8: =IF(ISBLANK(Z8),"",VLOOKUP(Z8,'(Linked) Hazard Risk Number HRN'!$B$6:$C$13,2,FALSE)) | AB8: =IF(AB10="","",IF(AB10>500,'(Linked) Hazard Risk Number HRN'!$C$37,IF(AB10>50,'(Linked) Hazard Risk Number HRN'!$C$36,IF(AB10>25,'(Linked) Hazard Risk Number HRN'!$C$35,IF(AB10>5,'(Linked) Hazard Risk Number HRN'!$C$34,IF(AB10>0,'(Linked) Hazard Risk Number HRN'!$C$33,"")))))) | AC8: Detección de presencia: Añadir cortina de luz | AE8: Very Minor: Basic first aid (small cut, swelling) (adhesive bandage, ice pack, non-rigid supports) | AF8: =IF(ISBLANK(AE8),"",VLOOKUP(AE8,'(Linked) Hazard Risk Number HRN'!$B$6:$C$13,2,FALSE)) | AG8: =IF(AG10="","",IF(AG10>500,'(Linked) Hazard Risk Number HRN'!$C$37,IF(AG10>50,'(Linked) Hazard Risk Number HRN'!$C$36,IF(AG10>25,'(Linked) Hazard Risk Number HRN'!$C$35,IF(AG10>5,'(Linked) Hazard Risk Number HRN'!$C$34,IF(AG10>0,'(Linked) Hazard Risk Number HRN'!$C$33,""))))))
K9: Constantly or Greater than once each 15 minutes | L9: =IF(ISBLANK(K9),"",VLOOKUP(K9,'(Linked) Hazard Risk Number HRN'!$B$16:$C$26,2,FALSE)) | N9: Mid speed event e.g. 250 mm/s to 1000mm/s, time to hazard ≥1s and <3s, and/or limited time to escape | O9: =IF(ISBLANK(N9),"",VLOOKUP(N9,'(Linked) PLr Probability Factor'!$B$12:$C$14,2,FALSE)) | P9: B | Q9: =COUNTIF((O8:O12), "B") -> 0 | R9: =Q9 -> 0 | S9: =IF(ISBLANK(K9),"",IF(L9<5,"F1","F2")) | V9: Constantly or Greater than once each 15 minutes | W9: =IF(ISBLANK(V9),"",VLOOKUP(V9,'(Linked) Hazard Risk Number HRN'!$B$16:$C$26,2,FALSE)) | Z9: Constantly or Greater than once each 15 minutes | AA9: =IF(ISBLANK(Z9),"",VLOOKUP(Z9,'(Linked) Hazard Risk Number HRN'!$B$16:$C$26,2,FALSE)) | AE9: Constantly or Greater than once each 15 minutes | AF9: =IF(ISBLANK(AE9),"",VLOOKUP(AE9,'(Linked) Hazard Risk Number HRN'!$B$16:$C$26,2,FALSE))
K10: Possible but unusual | L10: =IF(ISBLANK(K10),"",VLOOKUP(K10,'(Linked) Hazard Risk Number HRN'!$D$6:$E$14,2,FALSE)) | M10: =IF(OR(ISBLANK(K8),ISBLANK(K9),ISBLANK(K10),ISBLANK(K11)),"",L8*L9*L10*L11) | N10: Easily possible (possible in ≥ 50% of the cases) | O10: =IF(ISBLANK(N10),"",VLOOKUP(N10,'(Linked) PLr Probability Factor'!$B$17:$C$20,2,FALSE)) | P10: A | Q10: =COUNTIF((O8:O12), "A") -> 0 | R10: =Q10 -> 0 | T10: {=IF(OR(ISBLANK(K8),ISBLANK(K9),ISBLANK(N9),ISBLANK(N10),ISBLANK(N11)),"",INDEX(INDEX('(Linked) PLr Probability Factor'!C$33:$F$44,0,4),MATCH(S8&S9&S12,INDEX('(Linked) PLr Probability Factor'!C$33:$F$44,0,1)&INDEX('(Linked) PLr Probability Factor'!C$33:$F$44,0,2)&INDEX('(Linked) PLr Probability Factor'!C$33:$F$44,0,3),0)))} | V10: Almost impossible, possible only under extreme circumstances | W10: =IF(ISBLANK(V10),"",VLOOKUP(V10,'(Linked) Hazard Risk Number HRN'!$D$6:$E$14,2,FALSE)) | X10: =IF(OR(ISBLANK(V8),ISBLANK(V9),ISBLANK(V10),ISBLANK(V11)),"",W8*W9*W10*W11) | Z10: Almost impossible, possible only under extreme circumstances | AA10: =IF(ISBLANK(Z10),"",VLOOKUP(Z10,'(Linked) Hazard Risk Number HRN'!$D$6:$E$14,2,FALSE)) | AB10: =IF(OR(ISBLANK(Z8),ISBLANK(Z9),ISBLANK(Z10),ISBLANK(Z11)),"",AA8*AA9*AA10*AA11) | AE10: Almost impossible, possible only under extreme circumstances | AF10: =IF(ISBLANK(AE10),"",VLOOKUP(AE10,'(Linked) Hazard Risk Number HRN'!$D$6:$E$14,2,FALSE)) | AG10: =IF(OR(ISBLANK(AE8),ISBLANK(AE9),ISBLANK(AE10),ISBLANK(AE11)),"",AF8*AF9*AF10*AF11)
K11: 1 to 2 persons | L11: =IF(ISBLANK(K11),"",VLOOKUP(K11,'(Linked) Hazard Risk Number HRN'!$D$17:$E$22,2,FALSE)) | N11: Easy recognition of the hazard (possible in ≥ 50% of the cases) | O11: =IF(ISBLANK(N11),"",VLOOKUP(N11,'(Linked) PLr Probability Factor'!$B$23:$C$26,2,FALSE)) | P11: Total | Q11: =SUM(R8:R10) -> 0 | R11: =Q11 -> 0 | V11: 1 to 2 persons | W11: =IF(ISBLANK(V11),"",VLOOKUP(V11,'(Linked) Hazard Risk Number HRN'!$D$17:$E$22,2,FALSE)) | Z11: 1 to 2 persons | AA11: =IF(ISBLANK(Z11),"",VLOOKUP(Z11,'(Linked) Hazard Risk Number HRN'!$D$17:$E$22,2,FALSE)) | AE11: 1 to 2 persons | AF11: =IF(ISBLANK(AE11),"",VLOOKUP(AE11,'(Linked) Hazard Risk Number HRN'!$D$17:$E$22,2,FALSE))
N12: Low complexity / no interaction (e.g. adjust clamps, load a workpiece) | O12: =IF(ISBLANK(N12),"",VLOOKUP(N12,'(Linked) PLr Probability Factor'!$B$29:$C$32,2,FALSE)) | S12: =IF(OR(ISBLANK(N9),ISBLANK(N10),ISBLANK(N11)),"",IF(R8>0,"P2",IF(AND(R8=0,R9>2),"P2",IF(AND(R8=0,R9=2),"P2",IF(AND(R8=0,AND(R9<2,R10>1)),"P1"," ")))))
B13: 2 | C13: Operación normal | D13: Mecánica: transportador/rodillo; punto de pellizco/apriete | G13: X | K13: Moderate: Significant medical attention (severe laceration), physical therapy (restricted duties <2 weeks) | L13: =IF(ISBLANK(K13),"",VLOOKUP(K13,'(Linked) Hazard Risk Number HRN'!$B$6:$C$13,2,FALSE)) | M13: =IF(M15="","",IF(M15>500,'(Linked) Hazard Risk Number HRN'!$C$37,IF(M15>50,'(Linked) Hazard Risk Number HRN'!$C$36,IF(M15>25,'(Linked) Hazard Risk Number HRN'!$C$35,IF(M15>5,'(Linked) Hazard Risk Number HRN'!$C$34,IF(M15>0,'(Linked) Hazard Risk Number HRN'!$C$33,"")))))) | N13: Unskilled person | O13: =IF(ISBLANK(N13),"",VLOOKUP(N13,'(Linked) PLr Probability Factor'!$B$7:$C$8,2,FALSE)) | P13: C | Q13: =COUNTIF((O13:O17), "C") -> 0 | R13: =Q13 -> 0 | S13: =IF(ISBLANK(K13),"",IF(L13<2,"S1","S2")) | U13: Detección de presencia: Añadir cortina de luz | V13: Very Minor: Basic first aid (small cut, swelling) (adhesive bandage, ice pack, non-rigid supports) | W13: =IF(ISBLANK(V13),"",VLOOKUP(V13,'(Linked) Hazard Risk Number HRN'!$B$6:$C$13,2,FALSE)) | X13: =IF(X15="","",IF(X15>500,'(Linked) Hazard Risk Number HRN'!$C$37,IF(X15>50,'(Linked) Hazard Risk Number HRN'!$C$36,IF(X15>25,'(Linked) Hazard Risk Number HRN'!$C$35,IF(X15>5,'(Linked) Hazard Risk Number HRN'!$C$34,IF(X15>0,'(Linked) Hazard Risk Number HRN'!$C$33,"")))))) | Y13: Procedimiento / Implementación de SOP | Z13: Very Minor: Basic first aid (small cut, swelling) (adhesive bandage, ice pack, non-rigid supports) | AA13: =IF(ISBLANK(Z13),"",VLOOKUP(Z13,'(Linked) Hazard Risk Number HRN'!$B$6:$C$13,2,FALSE)) | AB13: =IF(AB15="","",IF(AB15>500,'(Linked) Hazard Risk Number HRN'!$C$37,IF(AB15>50,'(Linked) Hazard Risk Number HRN'!$C$36,IF(AB15>25,'(Linked) Hazard Risk Number HRN'!$C$35,IF(AB15>5,'(Linked) Hazard Risk Number HRN'!$C$34,IF(AB15>0,'(Linked) Hazard Risk Number HRN'!$C$33,"")))))) | AC13: Detección de presencia: Añadir cortina de luz | AE13: Very Minor: Basic first aid (small cut, swelling) (adhesive bandage, ice pack, non-rigid supports) | AF13: =IF(ISBLANK(AE13),"",VLOOKUP(AE13,'(Linked) Hazard Risk Number HRN'!$B$6:$C$13,2,FALSE)) | AG13: =IF(AG15="","",IF(AG15>500,'(Linked) Hazard Risk Number HRN'!$C$37,IF(AG15>50,'(Linked) Hazard Risk Number HRN'!$C$36,IF(AG15>25,'(Linked) Hazard Risk Number HRN'!$C$35,IF(AG15>5,'(Linked) Hazard Risk Number HRN'!$C$34,IF(AG15>0,'(Linked) Hazard Risk Number HRN'!$C$33,""))))))
K14: Constantly or Greater than once each 15 minutes | L14: =IF(ISBLANK(K14),"",VLOOKUP(K14,'(Linked) Hazard Risk Number HRN'!$B$16:$C$26,2,FALSE)) | N14: Mid speed event e.g. 250 mm/s to 1000mm/s, time to hazard ≥1s and <3s, and/or limited time to escape | O14: =IF(ISBLANK(N14),"",VLOOKUP(N14,'(Linked) PLr Probability Factor'!$B$12:$C$14,2,FALSE)) | P14: B | Q14: =COUNTIF((O13:O17), "B") -> 0 | R14: =Q14 -> 0 | S14: =IF(ISBLANK(K14),"",IF(L14<5,"F1","F2")) | V14: Constantly or Greater than once each 15 minutes | W14: =IF(ISBLANK(V14),"",VLOOKUP(V14,'(Linked) Hazard Risk Number HRN'!$B$16:$C$26,2,FALSE)) | Z14: Constantly or Greater than once each 15 minutes | AA14: =IF(ISBLANK(Z14),"",VLOOKUP(Z14,'(Linked) Hazard Risk Number HRN'!$B$16:$C$26,2,FALSE)) | AE14: Constantly or Greater than once each 15 minutes | AF14: =IF(ISBLANK(AE14),"",VLOOKUP(AE14,'(Linked) Hazard Risk Number HRN'!$B$16:$C$26,2,FALSE))
K15: Possible but unusual | L15: =IF(ISBLANK(K15),"",VLOOKUP(K15,'(Linked) Hazard Risk Number HRN'!$D$6:$E$14,2,FALSE)) | M15: =IF(OR(ISBLANK(K13),ISBLANK(K14),ISBLANK(K15),ISBLANK(K16)),"",L13*L14*L15*L16) | N15: Easily possible (possible in ≥ 50% of the cases) | O15: =IF(ISBLANK(N15),"",VLOOKUP(N15,'(Linked) PLr Probability Factor'!$B$17:$C$20,2,FALSE)) | P15: A | Q15: =COUNTIF((O13:O17), "A") -> 0 | R15: =Q15 -> 0 | T15: {=IF(OR(ISBLANK(K13),ISBLANK(K14),ISBLANK(N14),ISBLANK(N15),ISBLANK(N16)),"",INDEX(INDEX('(Linked) PLr Probability Factor'!C$33:$F$44,0,4),MATCH(S13&S14&S17,INDEX('(Linked) PLr Probability Factor'!C$33:$F$44,0,1)&INDEX('(Linked) PLr Probability Factor'!C$33:$F$44,0,2)&INDEX('(Linked) PLr Probability Factor'!C$33:$F$44,0,3),0)))} | V15: Almost impossible, possible only under extreme circumstances | W15: =IF(ISBLANK(V15),"",VLOOKUP(V15,'(Linked) Hazard Risk Number HRN'!$D$6:$E$14,2,FALSE)) | X15: =IF(OR(ISBLANK(V13),ISBLANK(V14),ISBLANK(V15),ISBLANK(V16)),"",W13*W14*W15*W16) | Z15: Almost impossible, possible only under extreme circumstances | AA15: =IF(ISBLANK(Z15),"",VLOOKUP(Z15,'(Linked) Hazard Risk Number HRN'!$D$6:$E$14,2,FALSE)) | AB15: =IF(OR(ISBLANK(Z13),ISBLANK(Z14),ISBLANK(Z15),ISBLANK(Z16)),"",AA13*AA14*AA15*AA16) | AE15: Almost impossible, possible only under extreme circumstances | AF15: =IF(ISBLANK(AE15),"",VLOOKUP(AE15,'(Linked) Hazard Risk Number HRN'!$D$6:$E$14,2,FALSE)) | AG15: =IF(OR(ISBLANK(AE13),ISBLANK(AE14),ISBLANK(AE15),ISBLANK(AE16)),"",AF13*AF14*AF15*AF16)
K16: 1 to 2 persons | L16: =IF(ISBLANK(K16),"",VLOOKUP(K16,'(Linked) Hazard Risk Number HRN'!$D$17:$E$22,2,FALSE)) | N16: Easy recognition of the hazard (possible in ≥ 50% of the cases) | O16: =IF(ISBLANK(N16),"",VLOOKUP(N16,'(Linked) PLr Probability Factor'!$B$23:$C$26,2,FALSE)) | P16: Total | Q16: =SUM(R13:R15) -> 0 | R16: =Q16 -> 0 | V16: 1 to 2 persons | W16: =IF(ISBLANK(V16),"",VLOOKUP(V16,'(Linked) Hazard Risk Number HRN'!$D$17:$E$22,2,FALSE)) | Z16: 1 to 2 persons | AA16: =IF(ISBLANK(Z16),"",VLOOKUP(Z16,'(Linked) Hazard Risk Number HRN'!$D$17:$E$22,2,FALSE)) | AE16: 1 to 2 persons | AF16: =IF(ISBLANK(AE16),"",VLOOKUP(AE16,'(Linked) Hazard Risk Number HRN'!$D$17:$E$22,2,FALSE))
N17: Low complexity / no interaction (e.g. adjust clamps, load a workpiece) | O17: =IF(ISBLANK(N17),"",VLOOKUP(N17,'(Linked) PLr Probability Factor'!$B$29:$C$32,2,FALSE)) | S17: =IF(OR(ISBLANK(N14),ISBLANK(N15),ISBLANK(N16)),"",IF(R13>0,"P2",IF(AND(R13=0,R14>2),"P2",IF(AND(R13=0,R14=2),"P2",IF(AND(R13=0,AND(R14<2,R15>1)),"P1"," ")))))
B18: 3 | C18: Operación normal | D18: Mecánica: transmisión; pinchazo/aplastamiento/enredamiento. | G18: X | K18: Moderate: Significant medical attention (severe laceration), physical therapy (restricted duties <2 weeks) | L18: =IF(ISBLANK(K18),"",VLOOKUP(K18,'(Linked) Hazard Risk Number HRN'!$B$6:$C$13,2,FALSE)) | M18: =IF(M20="","",IF(M20>500,'(Linked) Hazard Risk Number HRN'!$C$37,IF(M20>50,'(Linked) Hazard Risk Number HRN'!$C$36,IF(M20>25,'(Linked) Hazard Risk Number HRN'!$C$35,IF(M20>5,'(Linked) Hazard Risk Number HRN'!$C$34,IF(M20>0,'(Linked) Hazard Risk Number HRN'!$C$33,"")))))) | N18: Unskilled person | O18: =IF(ISBLANK(N18),"",VLOOKUP(N18,'(Linked) PLr Probability Factor'!$B$7:$C$8,2,FALSE)) | P18: C | Q18: =COUNTIF((O18:O22), "C") -> 0 | R18: =Q18 -> 0 | S18: =IF(ISBLANK(K18),"",IF(L18<2,"S1","S2")) | U18: Detección de presencia: Añadir cortina de luz | V18: Very Minor: Basic first aid (small cut, swelling) (adhesive bandage, ice pack, non-rigid supports) | W18: =IF(ISBLANK(V18),"",VLOOKUP(V18,'(Linked) Hazard Risk Number HRN'!$B$6:$C$13,2,FALSE)) | X18: =IF(X20="","",IF(X20>500,'(Linked) Hazard Risk Number HRN'!$C$37,IF(X20>50,'(Linked) Hazard Risk Number HRN'!$C$36,IF(X20>25,'(Linked) Hazard Risk Number HRN'!$C$35,IF(X20>5,'(Linked) Hazard Risk Number HRN'!$C$34,IF(X20>0,'(Linked) Hazard Risk Number HRN'!$C$33,"")))))) | Y18: Procedimiento / Implementación de SOP | Z18: Very Minor: Basic first aid (small cut, swelling) (adhesive bandage, ice pack, non-rigid supports) | AA18: =IF(ISBLANK(Z18),"",VLOOKUP(Z18,'(Linked) Hazard Risk Number HRN'!$B$6:$C$13,2,FALSE)) | AB18: =IF(AB20="","",IF(AB20>500,'(Linked) Hazard Risk Number HRN'!$C$37,IF(AB20>50,'(Linked) Hazard Risk Number HRN'!$C$36,IF(AB20>25,'(Linked) Hazard Risk Number HRN'!$C$35,IF(AB20>5,'(Linked) Hazard Risk Number HRN'!$C$34,IF(AB20>0,'(Linked) Hazard Risk Number HRN'!$C$33,"")))))) | AC18: Detección de presencia: Añadir cortina de luz | AE18: Very Minor: Basic first aid (small cut, swelling) (adhesive bandage, ice pack, non-rigid supports) | AF18: =IF(ISBLANK(AE18),"",VLOOKUP(AE18,'(Linked) Hazard Risk Number HRN'!$B$6:$C$13,2,FALSE)) | AG18: =IF(AG20="","",IF(AG20>500,'(Linked) Hazard Risk Number HRN'!$C$37,IF(AG20>50,'(Linked) Hazard Risk Number HRN'!$C$36,IF(AG20>25,'(Linked) Hazard Risk Number HRN'!$C$35,IF(AG20>5,'(Linked) Hazard Risk Number HRN'!$C$34,IF(AG20>0,'(Linked) Hazard Risk Number HRN'!$C$33,""))))))
K19: Constantly or Greater than once each 15 minutes | L19: =IF(ISBLANK(K19),"",VLOOKUP(K19,'(Linked) Hazard Risk Number HRN'!$B$16:$C$26,2,FALSE)) | N19: Mid speed event e.g. 250 mm/s to 1000mm/s, time to hazard ≥1s and <3s, and/or limited time to escape | O19: =IF(ISBLANK(N19),"",VLOOKUP(N19,'(Linked) PLr Probability Factor'!$B$12:$C$14,2,FALSE)) | P19: B | Q19: =COUNTIF((O18:O22), "B") -> 0 | R19: =Q19 -> 0 | S19: =IF(ISBLANK(K19),"",IF(L19<5,"F1","F2")) | V19: Constantly or Greater than once each 15 minutes | W19: =IF(ISBLANK(V19),"",VLOOKUP(V19,'(Linked) Hazard Risk Number HRN'!$B$16:$C$26,2,FALSE)) | Z19: Constantly or Greater than once each 15 minutes | AA19: =IF(ISBLANK(Z19),"",VLOOKUP(Z19,'(Linked) Hazard Risk Number HRN'!$B$16:$C$26,2,FALSE)) | AE19: Constantly or Greater than once each 15 minutes | AF19: =IF(ISBLANK(AE19),"",VLOOKUP(AE19,'(Linked) Hazard Risk Number HRN'!$B$16:$C$26,2,FALSE))
K20: Possible but unusual | L20: =IF(ISBLANK(K20),"",VLOOKUP(K20,'(Linked) Hazard Risk Number HRN'!$D$6:$E$14,2,FALSE)) | M20: =IF(OR(ISBLANK(K18),ISBLANK(K19),ISBLANK(K20),ISBLANK(K21)),"",L18*L19*L20*L21) | N20: Easily possible (possible in ≥ 50% of the cases) | O20: =IF(ISBLANK(N20),"",VLOOKUP(N20,'(Linked) PLr Probability Factor'!$B$17:$C$20,2,FALSE)) | P20: A | Q20: =COUNTIF((O18:O22), "A") -> 0 | R20: =Q20 -> 0 | T20: {=IF(OR(ISBLANK(K18),ISBLANK(K19),ISBLANK(N19),ISBLANK(N20),ISBLANK(N21)),"",INDEX(INDEX('(Linked) PLr Probability Factor'!C$33:$F$44,0,4),MATCH(S18&S19&S22,INDEX('(Linked) PLr Probability Factor'!C$33:$F$44,0,1)&INDEX('(Linked) PLr Probability Factor'!C$33:$F$44,0,2)&INDEX('(Linked) PLr Probability Factor'!C$33:$F$44,0,3),0)))} | V20: Almost impossible, possible only under extreme circumstances | W20: =IF(ISBLANK(V20),"",VLOOKUP(V20,'(Linked) Hazard Risk Number HRN'!$D$6:$E$14,2,FALSE)) | X20: =IF(OR(ISBLANK(V18),ISBLANK(V19),ISBLANK(V20),ISBLANK(V21)),"",W18*W19*W20*W21) | Z20: Almost impossible, possible only under extreme circumstances | AA20: =IF(ISBLANK(Z20),"",VLOOKUP(Z20,'(Linked) Hazard Risk Number HRN'!$D$6:$E$14,2,FALSE)) | AB20: =IF(OR(ISBLANK(Z18),ISBLANK(Z19),ISBLANK(Z20),ISBLANK(Z21)),"",AA18*AA19*AA20*AA21) | AE20: Almost impossible, possible only under extreme circumstances | AF20: =IF(ISBLANK(AE20),"",VLOOKUP(AE20,'(Linked) Hazard Risk Number HRN'!$D$6:$E$14,2,FALSE)) | AG20: =IF(OR(ISBLANK(AE18),ISBLANK(AE19),ISBLANK(AE20),ISBLANK(AE21)),"",AF18*AF19*AF20*AF21)
K21: 1 to 2 persons | L21: =IF(ISBLANK(K21),"",VLOOKUP(K21,'(Linked) Hazard Risk Number HRN'!$D$17:$E$22,2,FALSE)) | N21: Easy recognition of the hazard (possible in ≥ 50% of the cases) | O21: =IF(ISBLANK(N21),"",VLOOKUP(N21,'(Linked) PLr Probability Factor'!$B$23:$C$26,2,FALSE)) | P21: Total | Q21: =SUM(R18:R20) -> 0 | R21: =Q21 -> 0 | V21: 1 to 2 persons | W21: =IF(ISBLANK(V21),"",VLOOKUP(V21,'(Linked) Hazard Risk Number HRN'!$D$17:$E$22,2,FALSE)) | Z21: 1 to 2 persons | AA21: =IF(ISBLANK(Z21),"",VLOOKUP(Z21,'(Linked) Hazard Risk Number HRN'!$D$17:$E$22,2,FALSE)) | AE21: 1 to 2 persons | AF21: =IF(ISBLANK(AE21),"",VLOOKUP(AE21,'(Linked) Hazard Risk Number HRN'!$D$17:$E$22,2,FALSE))
N22: Low complexity / no interaction (e.g. adjust clamps, load a workpiece) | O22: =IF(ISBLANK(N22),"",VLOOKUP(N22,'(Linked) PLr Probability Factor'!$B$29:$C$32,2,FALSE)) | S22: =IF(OR(ISBLANK(N19),ISBLANK(N20),ISBLANK(N21)),"",IF(R18>0,"P2",IF(AND(R18=0,R19>2),"P2",IF(AND(R18=0,R19=2),"P2",IF(AND(R18=0,AND(R19<2,R20>1)),"P1"," ")))))
B23: 4 | C23: Manejo de materiales | D23: Mecánica: transmisión; pinchazo/aplastamiento/enredamiento. | G23: X | K23: Major: Severe Injury, bone break/fracture, general surgery, written out of work (restricted duties >2weeks<6 months) | L23: =IF(ISBLANK(K23),"",VLOOKUP(K23,'(Linked) Hazard Risk Number HRN'!$B$6:$C$13,2,FALSE)) | M23: =IF(M25="","",IF(M25>500,'(Linked) Hazard Risk Number HRN'!$C$37,IF(M25>50,'(Linked) Hazard Risk Number HRN'!$C$36,IF(M25>25,'(Linked) Hazard Risk Number HRN'!$C$35,IF(M25>5,'(Linked) Hazard Risk Number HRN'!$C$34,IF(M25>0,'(Linked) Hazard Risk Number HRN'!$C$33,"")))))) | N23: Unskilled person | O23: =IF(ISBLANK(N23),"",VLOOKUP(N23,'(Linked) PLr Probability Factor'!$B$7:$C$8,2,FALSE)) | P23: C | Q23: =COUNTIF((O23:O27), "C") -> 0 | R23: =Q23 -> 0 | S23: =IF(ISBLANK(K23),"",IF(L23<2,"S1","S2")) | U23: Control de acceso: controles a dos manos | V23: Very Minor: Basic first aid (small cut, swelling) (adhesive bandage, ice pack, non-rigid supports) | W23: =IF(ISBLANK(V23),"",VLOOKUP(V23,'(Linked) Hazard Risk Number HRN'!$B$6:$C$13,2,FALSE)) | X23: =IF(X25="","",IF(X25>500,'(Linked) Hazard Risk Number HRN'!$C$37,IF(X25>50,'(Linked) Hazard Risk Number HRN'!$C$36,IF(X25>25,'(Linked) Hazard Risk Number HRN'!$C$35,IF(X25>5,'(Linked) Hazard Risk Number HRN'!$C$34,IF(X25>0,'(Linked) Hazard Risk Number HRN'!$C$33,"")))))) | Y23: Procedimiento / Implementación de SOP | Z23: Very Minor: Basic first aid (small cut, swelling) (adhesive bandage, ice pack, non-rigid supports) | AA23: =IF(ISBLANK(Z23),"",VLOOKUP(Z23,'(Linked) Hazard Risk Number HRN'!$B$6:$C$13,2,FALSE)) | AB23: =IF(AB25="","",IF(AB25>500,'(Linked) Hazard Risk Number HRN'!$C$37,IF(AB25>50,'(Linked) Hazard Risk Number HRN'!$C$36,IF(AB25>25,'(Linked) Hazard Risk Number HRN'!$C$35,IF(AB25>5,'(Linked) Hazard Risk Number HRN'!$C$34,IF(AB25>0,'(Linked) Hazard Risk Number HRN'!$C$33,"")))))) | AC23: Control de acceso: controles a dos manos | AE23: Very Minor: Basic first aid (small cut, swelling) (adhesive bandage, ice pack, non-rigid supports) | AF23: =IF(ISBLANK(AE23),"",VLOOKUP(AE23,'(Linked) Hazard Risk Number HRN'!$B$6:$C$13,2,FALSE)) | AG23: =IF(AG25="","",IF(AG25>500,'(Linked) Hazard Risk Number HRN'!$C$37,IF(AG25>50,'(Linked) Hazard Risk Number HRN'!$C$36,IF(AG25>25,'(Linked) Hazard Risk Number HRN'!$C$35,IF(AG25>5,'(Linked) Hazard Risk Number HRN'!$C$34,IF(AG25>0,'(Linked) Hazard Risk Number HRN'!$C$33,""))))))
K24: Constantly or Greater than once each 15 minutes | L24: =IF(ISBLANK(K24),"",VLOOKUP(K24,'(Linked) Hazard Risk Number HRN'!$B$16:$C$26,2,FALSE)) | N24: Mid speed event e.g. 250 mm/s to 1000mm/s, time to hazard ≥1s and <3s, and/or limited time to escape | O24: =IF(ISBLANK(N24),"",VLOOKUP(N24,'(Linked) PLr Probability Factor'!$B$12:$C$14,2,FALSE)) | P24: B | Q24: =COUNTIF((O23:O27), "B") -> 0 | R24: =Q24 -> 0 | S24: =IF(ISBLANK(K24),"",IF(L24<5,"F1","F2")) | V24: Constantly or Greater than once each 15 minutes | W24: =IF(ISBLANK(V24),"",VLOOKUP(V24,'(Linked) Hazard Risk Number HRN'!$B$16:$C$26,2,FALSE)) | Z24: Constantly or Greater than once each 15 minutes | AA24: =IF(ISBLANK(Z24),"",VLOOKUP(Z24,'(Linked) Hazard Risk Number HRN'!$B$16:$C$26,2,FALSE)) | AE24: Constantly or Greater than once each 15 minutes | AF24: =IF(ISBLANK(AE24),"",VLOOKUP(AE24,'(Linked) Hazard Risk Number HRN'!$B$16:$C$26,2,FALSE))
K25: Even chance, could happen | L25: =IF(ISBLANK(K25),"",VLOOKUP(K25,'(Linked) Hazard Risk Number HRN'!$D$6:$E$14,2,FALSE)) | M25: =IF(OR(ISBLANK(K23),ISBLANK(K24),ISBLANK(K25),ISBLANK(K26)),"",L23*L24*L25*L26) | N25: Occasionally/rarely possible (possible in <50% of the cases) | O25: =IF(ISBLANK(N25),"",VLOOKUP(N25,'(Linked) PLr Probability Factor'!$B$17:$C$20,2,FALSE)) | P25: A | Q25: =COUNTIF((O23:O27), "A") -> 0 | R25: =Q25 -> 0 | T25: {=IF(OR(ISBLANK(K23),ISBLANK(K24),ISBLANK(N24),ISBLANK(N25),ISBLANK(N26)),"",INDEX(INDEX('(Linked) PLr Probability Factor'!C$33:$F$44,0,4),MATCH(S23&S24&S27,INDEX('(Linked) PLr Probability Factor'!C$33:$F$44,0,1)&INDEX('(Linked) PLr Probability Factor'!C$33:$F$44,0,2)&INDEX('(Linked) PLr Probability Factor'!C$33:$F$44,0,3),0)))} | V25: Highly unlikely though conceivable | W25: =IF(ISBLANK(V25),"",VLOOKUP(V25,'(Linked) Hazard Risk Number HRN'!$D$6:$E$14,2,FALSE)) | X25: =IF(OR(ISBLANK(V23),ISBLANK(V24),ISBLANK(V25),ISBLANK(V26)),"",W23*W24*W25*W26) | Z25: Highly unlikely though conceivable | AA25: =IF(ISBLANK(Z25),"",VLOOKUP(Z25,'(Linked) Hazard Risk Number HRN'!$D$6:$E$14,2,FALSE)) | AB25: =IF(OR(ISBLANK(Z23),ISBLANK(Z24),ISBLANK(Z25),ISBLANK(Z26)),"",AA23*AA24*AA25*AA26) | AE25: Highly unlikely though conceivable | AF25: =IF(ISBLANK(AE25),"",VLOOKUP(AE25,'(Linked) Hazard Risk Number HRN'!$D$6:$E$14,2,FALSE)) | AG25: =IF(OR(ISBLANK(AE23),ISBLANK(AE24),ISBLANK(AE25),ISBLANK(AE26)),"",AF23*AF24*AF25*AF26)
K26: 1 to 2 persons | L26: =IF(ISBLANK(K26),"",VLOOKUP(K26,'(Linked) Hazard Risk Number HRN'!$D$17:$E$22,2,FALSE)) | N26: Easy recognition of the hazard (possible in ≥ 50% of the cases) | O26: =IF(ISBLANK(N26),"",VLOOKUP(N26,'(Linked) PLr Probability Factor'!$B$23:$C$26,2,FALSE)) | P26: Total | Q26: =SUM(R23:R25) -> 0 | R26: =Q26 -> 0 | V26: 1 to 2 persons | W26: =IF(ISBLANK(V26),"",VLOOKUP(V26,'(Linked) Hazard Risk Number HRN'!$D$17:$E$22,2,FALSE)) | Z26: 1 to 2 persons | AA26: =IF(ISBLANK(Z26),"",VLOOKUP(Z26,'(Linked) Hazard Risk Number HRN'!$D$17:$E$22,2,FALSE)) | AE26: 1 to 2 persons | AF26: =IF(ISBLANK(AE26),"",VLOOKUP(AE26,'(Linked) Hazard Risk Number HRN'!$D$17:$E$22,2,FALSE))
N27: Low complexity / no interaction (e.g. adjust clamps, load a workpiece) | O27: =IF(ISBLANK(N27),"",VLOOKUP(N27,'(Linked) PLr Probability Factor'!$B$29:$C$32,2,FALSE)) | S27: =IF(OR(ISBLANK(N24),ISBLANK(N25),ISBLANK(N26)),"",IF(R23>0,"P2",IF(AND(R23=0,R24>2),"P2",IF(AND(R23=0,R24=2),"P2",IF(AND(R23=0,AND(R24<2,R25>1)),"P1"," ")))))
B28: 5 | C28: Operación normal | D28: Químicos / Humos | G28: X | K28: Minor: Medical attention( prescription medication, couple of stitches, skin glue) (fit for normal duties) | L28: =IF(ISBLANK(K28),"",VLOOKUP(K28,'(Linked) Hazard Risk Number HRN'!$B$6:$C$13,2,FALSE)) | M28: =IF(M30="","",IF(M30>500,'(Linked) Hazard Risk Number HRN'!$C$37,IF(M30>50,'(Linked) Hazard Risk Number HRN'!$C$36,IF(M30>25,'(Linked) Hazard Risk Number HRN'!$C$35,IF(M30>5,'(Linked) Hazard Risk Number HRN'!$C$34,IF(M30>0,'(Linked) Hazard Risk Number HRN'!$C$33,"")))))) | N28: Unskilled person | O28: =IF(ISBLANK(N28),"",VLOOKUP(N28,'(Linked) PLr Probability Factor'!$B$7:$C$8,2,FALSE)) | P28: C | Q28: =COUNTIF((O28:O32), "C") -> 0 | R28: =Q28 -> 0 | S28: =IF(ISBLANK(K28),"",IF(L28<2,"S1","S2")) | U28: Ninguno | V28: Very Minor: Basic first aid (small cut, swelling) (adhesive bandage, ice pack, non-rigid supports) | W28: =IF(ISBLANK(V28),"",VLOOKUP(V28,'(Linked) Hazard Risk Number HRN'!$B$6:$C$13,2,FALSE)) | X28: =IF(X30="","",IF(X30>500,'(Linked) Hazard Risk Number HRN'!$C$37,IF(X30>50,'(Linked) Hazard Risk Number HRN'!$C$36,IF(X30>25,'(Linked) Hazard Risk Number HRN'!$C$35,IF(X30>5,'(Linked) Hazard Risk Number HRN'!$C$34,IF(X30>0,'(Linked) Hazard Risk Number HRN'!$C$33,"")))))) | Y28: Evaluación EHS (ergo, ruido, químico, radiación) | Z28: Very Minor: Basic first aid (small cut, swelling) (adhesive bandage, ice pack, non-rigid supports) | AA28: =IF(ISBLANK(Z28),"",VLOOKUP(Z28,'(Linked) Hazard Risk Number HRN'!$B$6:$C$13,2,FALSE)) | AB28: =IF(AB30="","",IF(AB30>500,'(Linked) Hazard Risk Number HRN'!$C$37,IF(AB30>50,'(Linked) Hazard Risk Number HRN'!$C$36,IF(AB30>25,'(Linked) Hazard Risk Number HRN'!$C$35,IF(AB30>5,'(Linked) Hazard Risk Number HRN'!$C$34,IF(AB30>0,'(Linked) Hazard Risk Number HRN'!$C$33,"")))))) | AC28: Ninguno | AE28: Very Minor: Basic first aid (small cut, swelling) (adhesive bandage, ice pack, non-rigid supports) | AF28: =IF(ISBLANK(AE28),"",VLOOKUP(AE28,'(Linked) Hazard Risk Number HRN'!$B$6:$C$13,2,FALSE)) | AG28: =IF(AG30="","",IF(AG30>500,'(Linked) Hazard Risk Number HRN'!$C$37,IF(AG30>50,'(Linked) Hazard Risk Number HRN'!$C$36,IF(AG30>25,'(Linked) Hazard Risk Number HRN'!$C$35,IF(AG30>5,'(Linked) Hazard Risk Number HRN'!$C$34,IF(AG30>0,'(Linked) Hazard Risk Number HRN'!$C$33,""))))))
K29: Weekly | L29: =IF(ISBLANK(K29),"",VLOOKUP(K29,'(Linked) Hazard Risk Number HRN'!$B$16:$C$26,2,FALSE)) | N29: Low or very low speed event e.g. <250 mm/s, time to hazard ≥3s, and/or enough time to escape | O29: =IF(ISBLANK(N29),"",VLOOKUP(N29,'(Linked) PLr Probability Factor'!$B$12:$C$14,2,FALSE)) | P29: B | Q29: =COUNTIF((O28:O32), "B") -> 0 | R29: =Q29 -> 0 | S29: =IF(ISBLANK(K29),"",IF(L29<5,"F1","F2")) | V29: Weekly | W29: =IF(ISBLANK(V29),"",VLOOKUP(V29,'(Linked) Hazard Risk Number HRN'!$B$16:$C$26,2,FALSE)) | Z29: Weekly | AA29: =IF(ISBLANK(Z29),"",VLOOKUP(Z29,'(Linked) Hazard Risk Number HRN'!$B$16:$C$26,2,FALSE)) | AE29: Weekly | AF29: =IF(ISBLANK(AE29),"",VLOOKUP(AE29,'(Linked) Hazard Risk Number HRN'!$B$16:$C$26,2,FALSE))
K30: Possible but unusual | L30: =IF(ISBLANK(K30),"",VLOOKUP(K30,'(Linked) Hazard Risk Number HRN'!$D$6:$E$14,2,FALSE)) | M30: =IF(OR(ISBLANK(K28),ISBLANK(K29),ISBLANK(K30),ISBLANK(K31)),"",L28*L29*L30*L31) | N30: Easily possible (possible in ≥ 50% of the cases) | O30: =IF(ISBLANK(N30),"",VLOOKUP(N30,'(Linked) PLr Probability Factor'!$B$17:$C$20,2,FALSE)) | P30: A | Q30: =COUNTIF((O28:O32), "A") -> 0 | R30: =Q30 -> 0 | T30: {=IF(OR(ISBLANK(K28),ISBLANK(K29),ISBLANK(N29),ISBLANK(N30),ISBLANK(N31)),"",INDEX(INDEX('(Linked) PLr Probability Factor'!C$33:$F$44,0,4),MATCH(S28&S29&S32,INDEX('(Linked) PLr Probability Factor'!C$33:$F$44,0,1)&INDEX('(Linked) PLr Probability Factor'!C$33:$F$44,0,2)&INDEX('(Linked) PLr Probability Factor'!C$33:$F$44,0,3),0)))} | V30: Highly unlikely though conceivable | W30: =IF(ISBLANK(V30),"",VLOOKUP(V30,'(Linked) Hazard Risk Number HRN'!$D$6:$E$14,2,FALSE)) | X30: =IF(OR(ISBLANK(V28),ISBLANK(V29),ISBLANK(V30),ISBLANK(V31)),"",W28*W29*W30*W31) | Z30: Highly unlikely though conceivable | AA30: =IF(ISBLANK(Z30),"",VLOOKUP(Z30,'(Linked) Hazard Risk Number HRN'!$D$6:$E$14,2,FALSE)) | AB30: =IF(OR(ISBLANK(Z28),ISBLANK(Z29),ISBLANK(Z30),ISBLANK(Z31)),"",AA28*AA29*AA30*AA31) | AE30: Highly unlikely though conceivable | AF30: =IF(ISBLANK(AE30),"",VLOOKUP(AE30,'(Linked) Hazard Risk Number HRN'!$D$6:$E$14,2,FALSE)) | AG30: =IF(OR(ISBLANK(AE28),ISBLANK(AE29),ISBLANK(AE30),ISBLANK(AE31)),"",AF28*AF29*AF30*AF31)
K31: 1 to 2 persons | L31: =IF(ISBLANK(K31),"",VLOOKUP(K31,'(Linked) Hazard Risk Number HRN'!$D$17:$E$22,2,FALSE)) | N31: Occasionally/rare recognition of the hazard (possible in <50% of the cases) | O31: =IF(ISBLANK(N31),"",VLOOKUP(N31,'(Linked) PLr Probability Factor'!$B$23:$C$26,2,FALSE)) | P31: Total | Q31: =SUM(R28:R30) -> 0 | R31: =Q31 -> 0 | V31: 1 to 2 persons | W31: =IF(ISBLANK(V31),"",VLOOKUP(V31,'(Linked) Hazard Risk Number HRN'!$D$17:$E$22,2,FALSE)) | Z31: 1 to 2 persons | AA31: =IF(ISBLANK(Z31),"",VLOOKUP(Z31,'(Linked) Hazard Risk Number HRN'!$D$17:$E$22,2,FALSE)) | AE31: 1 to 2 persons | AF31: =IF(ISBLANK(AE31),"",VLOOKUP(AE31,'(Linked) Hazard Risk Number HRN'!$D$17:$E$22,2,FALSE))
N32: Low complexity / no interaction (e.g. adjust clamps, load a workpiece) | O32: =IF(ISBLANK(N32),"",VLOOKUP(N32,'(Linked) PLr Probability Factor'!$B$29:$C$32,2,FALSE)) | S32: =IF(OR(ISBLANK(N29),ISBLANK(N30),ISBLANK(N31)),"",IF(R28>0,"P2",IF(AND(R28=0,R29>2),"P2",IF(AND(R28=0,R29=2),"P2",IF(AND(R28=0,AND(R29<2,R30>1)),"P1"," ")))))
B33: 6 | C33: Lockout/Tryout (LOTO) | D33: Sistema de control: ciclo automático/arranque inesperado | H33: X | K33: Extreme: Immediate hospitalization, emergency surgery, permanent loss of limb/eyesight/function, long-term disability | L33: =IF(ISBLANK(K33),"",VLOOKUP(K33,'(Linked) Hazard Risk Number HRN'!$B$6:$C$13,2,FALSE)) | M33: =IF(M35="","",IF(M35>500,'(Linked) Hazard Risk Number HRN'!$C$37,IF(M35>50,'(Linked) Hazard Risk Number HRN'!$C$36,IF(M35>25,'(Linked) Hazard Risk Number HRN'!$C$35,IF(M35>5,'(Linked) Hazard Risk Number HRN'!$C$34,IF(M35>0,'(Linked) Hazard Risk Number HRN'!$C$33,"")))))) | N33: Unskilled person | O33: =IF(ISBLANK(N33),"",VLOOKUP(N33,'(Linked) PLr Probability Factor'!$B$7:$C$8,2,FALSE)) | P33: C | Q33: =COUNTIF((O33:O37), "C") -> 0 | R33: =Q33 -> 0 | S33: =IF(ISBLANK(K33),"",IF(L33<2,"S1","S2")) | U33: Actualizar los controles de seguridad con componentes clasificados para seguridad y reinicio de seguridad | V33: Extreme: Immediate hospitalization, emergency surgery, permanent loss of limb/eyesight/function, long-term disability | W33: =IF(ISBLANK(V33),"",VLOOKUP(V33,'(Linked) Hazard Risk Number HRN'!$B$6:$C$13,2,FALSE)) | X33: =IF(X35="","",IF(X35>500,'(Linked) Hazard Risk Number HRN'!$C$37,IF(X35>50,'(Linked) Hazard Risk Number HRN'!$C$36,IF(X35>25,'(Linked) Hazard Risk Number HRN'!$C$35,IF(X35>5,'(Linked) Hazard Risk Number HRN'!$C$34,IF(X35>0,'(Linked) Hazard Risk Number HRN'!$C$33,"")))))) | Y33: Mantenimiento: Procedimiento/SOP/LOTO | Z33: Extreme: Immediate hospitalization, emergency surgery, permanent loss of limb/eyesight/function, long-term disability | AA33: =IF(ISBLANK(Z33),"",VLOOKUP(Z33,'(Linked) Hazard Risk Number HRN'!$B$6:$C$13,2,FALSE)) | AB33: =IF(AB35="","",IF(AB35>500,'(Linked) Hazard Risk Number HRN'!$C$37,IF(AB35>50,'(Linked) Hazard Risk Number HRN'!$C$36,IF(AB35>25,'(Linked) Hazard Risk Number HRN'!$C$35,IF(AB35>5,'(Linked) Hazard Risk Number HRN'!$C$34,IF(AB35>0,'(Linked) Hazard Risk Number HRN'!$C$33,"")))))) | AC33: Actualizar los controles de seguridad con componentes clasificados para seguridad y reinicio de seguridad | AE33: Extreme: Immediate hospitalization, emergency surgery, permanent loss of limb/eyesight/function, long-term disability | AF33: =IF(ISBLANK(AE33),"",VLOOKUP(AE33,'(Linked) Hazard Risk Number HRN'!$B$6:$C$13,2,FALSE)) | AG33: =IF(AG35="","",IF(AG35>500,'(Linked) Hazard Risk Number HRN'!$C$37,IF(AG35>50,'(Linked) Hazard Risk Number HRN'!$C$36,IF(AG35>25,'(Linked) Hazard Risk Number HRN'!$C$35,IF(AG35>5,'(Linked) Hazard Risk Number HRN'!$C$34,IF(AG35>0,'(Linked) Hazard Risk Number HRN'!$C$33,""))))))
K34: Monthly | L34: =IF(ISBLANK(K34),"",VLOOKUP(K34,'(Linked) Hazard Risk Number HRN'!$B$16:$C$26,2,FALSE)) | N34: Low or very low speed event e.g. <250 mm/s, time to hazard ≥3s, and/or enough time to escape | O34: =IF(ISBLANK(N34),"",VLOOKUP(N34,'(Linked) PLr Probability Factor'!$B$12:$C$14,2,FALSE)) | P34: B | Q34: =COUNTIF((O33:O37), "B") -> 0 | R34: =Q34 -> 0 | S34: =IF(ISBLANK(K34),"",IF(L34<5,"F1","F2")) | V34: Monthly | W34: =IF(ISBLANK(V34),"",VLOOKUP(V34,'(Linked) Hazard Risk Number HRN'!$B$16:$C$26,2,FALSE)) | Z34: Monthly | AA34: =IF(ISBLANK(Z34),"",VLOOKUP(Z34,'(Linked) Hazard Risk Number HRN'!$B$16:$C$26,2,FALSE)) | AE34: Monthly | AF34: =IF(ISBLANK(AE34),"",VLOOKUP(AE34,'(Linked) Hazard Risk Number HRN'!$B$16:$C$26,2,FALSE))
K35: Unlikely but could occur | L35: =IF(ISBLANK(K35),"",VLOOKUP(K35,'(Linked) Hazard Risk Number HRN'!$D$6:$E$14,2,FALSE)) | M35: =IF(OR(ISBLANK(K33),ISBLANK(K34),ISBLANK(K35),ISBLANK(K36)),"",L33*L34*L35*L36) | N35: Occasionally/rarely possible (possible in <50% of the cases) | O35: =IF(ISBLANK(N35),"",VLOOKUP(N35,'(Linked) PLr Probability Factor'!$B$17:$C$20,2,FALSE)) | P35: A | Q35: =COUNTIF((O33:O37), "A") -> 0 | R35: =Q35 -> 0 | T35: {=IF(OR(ISBLANK(K33),ISBLANK(K34),ISBLANK(N34),ISBLANK(N35),ISBLANK(N36)),"",INDEX(INDEX('(Linked) PLr Probability Factor'!C$33:$F$44,0,4),MATCH(S33&S34&S37,INDEX('(Linked) PLr Probability Factor'!C$33:$F$44,0,1)&INDEX('(Linked) PLr Probability Factor'!C$33:$F$44,0,2)&INDEX('(Linked) PLr Probability Factor'!C$33:$F$44,0,3),0)))} | V35: Almost impossible, possible only under extreme circumstances | W35: =IF(ISBLANK(V35),"",VLOOKUP(V35,'(Linked) Hazard Risk Number HRN'!$D$6:$E$14,2,FALSE)) | X35: =IF(OR(ISBLANK(V33),ISBLANK(V34),ISBLANK(V35),ISBLANK(V36)),"",W33*W34*W35*W36) | Z35: Almost impossible, possible only under extreme circumstances | AA35: =IF(ISBLANK(Z35),"",VLOOKUP(Z35,'(Linked) Hazard Risk Number HRN'!$D$6:$E$14,2,FALSE)) | AB35: =IF(OR(ISBLANK(Z33),ISBLANK(Z34),ISBLANK(Z35),ISBLANK(Z36)),"",AA33*AA34*AA35*AA36) | AE35: Almost impossible, possible only under extreme circumstances | AF35: =IF(ISBLANK(AE35),"",VLOOKUP(AE35,'(Linked) Hazard Risk Number HRN'!$D$6:$E$14,2,FALSE)) | AG35: =IF(OR(ISBLANK(AE33),ISBLANK(AE34),ISBLANK(AE35),ISBLANK(AE36)),"",AF33*AF34*AF35*AF36)
K36: 1 to 2 persons | L36: =IF(ISBLANK(K36),"",VLOOKUP(K36,'(Linked) Hazard Risk Number HRN'!$D$17:$E$22,2,FALSE)) | N36: Occasionally/rare recognition of the hazard (possible in <50% of the cases) | O36: =IF(ISBLANK(N36),"",VLOOKUP(N36,'(Linked) PLr Probability Factor'!$B$23:$C$26,2,FALSE)) | P36: Total | Q36: =SUM(R33:R35) -> 0 | R36: =Q36 -> 0 | V36: 1 to 2 persons | W36: =IF(ISBLANK(V36),"",VLOOKUP(V36,'(Linked) Hazard Risk Number HRN'!$D$17:$E$22,2,FALSE)) | Z36: 1 to 2 persons | AA36: =IF(ISBLANK(Z36),"",VLOOKUP(Z36,'(Linked) Hazard Risk Number HRN'!$D$17:$E$22,2,FALSE)) | AE36: 1 to 2 persons | AF36: =IF(ISBLANK(AE36),"",VLOOKUP(AE36,'(Linked) Hazard Risk Number HRN'!$D$17:$E$22,2,FALSE))
N37: Medium to high complexity (e.g. troubleshooting, hold-to-run setup) | O37: =IF(ISBLANK(N37),"",VLOOKUP(N37,'(Linked) PLr Probability Factor'!$B$29:$C$32,2,FALSE)) | S37: =IF(OR(ISBLANK(N34),ISBLANK(N35),ISBLANK(N36)),"",IF(R33>0,"P2",IF(AND(R33=0,R34>2),"P2",IF(AND(R33=0,R34=2),"P2",IF(AND(R33=0,AND(R34<2,R35>1)),"P1"," ")))))
B38: 7 | C38: Lockout/Tryout (LOTO) | D38: Neumático - Categoría de control de seguridad | H38: X | K38: Moderate: Significant medical attention (severe laceration), physical therapy (restricted duties <2 weeks) | L38: =IF(ISBLANK(K38),"",VLOOKUP(K38,'(Linked) Hazard Risk Number HRN'!$B$6:$C$13,2,FALSE)) | M38: =IF(M40="","",IF(M40>500,'(Linked) Hazard Risk Number HRN'!$C$37,IF(M40>50,'(Linked) Hazard Risk Number HRN'!$C$36,IF(M40>25,'(Linked) Hazard Risk Number HRN'!$C$35,IF(M40>5,'(Linked) Hazard Risk Number HRN'!$C$34,IF(M40>0,'(Linked) Hazard Risk Number HRN'!$C$33,"")))))) | N38: Unskilled person | O38: =IF(ISBLANK(N38),"",VLOOKUP(N38,'(Linked) PLr Probability Factor'!$B$7:$C$8,2,FALSE)) | P38: C | Q38: =COUNTIF((O38:O42), "C") -> 0 | R38: =Q38 -> 0 | S38: =IF(ISBLANK(K38),"",IF(L38<2,"S1","S2")) | U38: Aislamiento neumático: válvula de seguridad; Bloquear/sangrado | V38: Negligible: No first aid (scratch / bruise) | W38: =IF(ISBLANK(V38),"",VLOOKUP(V38,'(Linked) Hazard Risk Number HRN'!$B$6:$C$13,2,FALSE)) | X38: =IF(X40="","",IF(X40>500,'(Linked) Hazard Risk Number HRN'!$C$37,IF(X40>50,'(Linked) Hazard Risk Number HRN'!$C$36,IF(X40>25,'(Linked) Hazard Risk Number HRN'!$C$35,IF(X40>5,'(Linked) Hazard Risk Number HRN'!$C$34,IF(X40>0,'(Linked) Hazard Risk Number HRN'!$C$33,"")))))) | Y38: Mantenimiento: Procedimiento/SOP/LOTO | Z38: Negligible: No first aid (scratch / bruise) | AA38: =IF(ISBLANK(Z38),"",VLOOKUP(Z38,'(Linked) Hazard Risk Number HRN'!$B$6:$C$13,2,FALSE)) | AB38: =IF(AB40="","",IF(AB40>500,'(Linked) Hazard Risk Number HRN'!$C$37,IF(AB40>50,'(Linked) Hazard Risk Number HRN'!$C$36,IF(AB40>25,'(Linked) Hazard Risk Number HRN'!$C$35,IF(AB40>5,'(Linked) Hazard Risk Number HRN'!$C$34,IF(AB40>0,'(Linked) Hazard Risk Number HRN'!$C$33,"")))))) | AC38: Aislamiento neumático: válvula de seguridad; Bloquear/sangrado | AE38: Negligible: No first aid (scratch / bruise) | AF38: =IF(ISBLANK(AE38),"",VLOOKUP(AE38,'(Linked) Hazard Risk Number HRN'!$B$6:$C$13,2,FALSE)) | AG38: =IF(AG40="","",IF(AG40>500,'(Linked) Hazard Risk Number HRN'!$C$37,IF(AG40>50,'(Linked) Hazard Risk Number HRN'!$C$36,IF(AG40>25,'(Linked) Hazard Risk Number HRN'!$C$35,IF(AG40>5,'(Linked) Hazard Risk Number HRN'!$C$34,IF(AG40>0,'(Linked) Hazard Risk Number HRN'!$C$33,""))))))
K39: Monthly | L39: =IF(ISBLANK(K39),"",VLOOKUP(K39,'(Linked) Hazard Risk Number HRN'!$B$16:$C$26,2,FALSE)) | N39: Low or very low speed event e.g. <250 mm/s, time to hazard ≥3s, and/or enough time to escape | O39: =IF(ISBLANK(N39),"",VLOOKUP(N39,'(Linked) PLr Probability Factor'!$B$12:$C$14,2,FALSE)) | P39: B | Q39: =COUNTIF((O38:O42), "B") -> 0 | R39: =Q39 -> 0 | S39: =IF(ISBLANK(K39),"",IF(L39<5,"F1","F2")) | V39: Monthly | W39: =IF(ISBLANK(V39),"",VLOOKUP(V39,'(Linked) Hazard Risk Number HRN'!$B$16:$C$26,2,FALSE)) | Z39: Monthly | AA39: =IF(ISBLANK(Z39),"",VLOOKUP(Z39,'(Linked) Hazard Risk Number HRN'!$B$16:$C$26,2,FALSE)) | AE39: Monthly | AF39: =IF(ISBLANK(AE39),"",VLOOKUP(AE39,'(Linked) Hazard Risk Number HRN'!$B$16:$C$26,2,FALSE))
K40: Unlikely but could occur | L40: =IF(ISBLANK(K40),"",VLOOKUP(K40,'(Linked) Hazard Risk Number HRN'!$D$6:$E$14,2,FALSE)) | M40: =IF(OR(ISBLANK(K38),ISBLANK(K39),ISBLANK(K40),ISBLANK(K41)),"",L38*L39*L40*L41) | N40: Easily possible (possible in ≥ 50% of the cases) | O40: =IF(ISBLANK(N40),"",VLOOKUP(N40,'(Linked) PLr Probability Factor'!$B$17:$C$20,2,FALSE)) | P40: A | Q40: =COUNTIF((O38:O42), "A") -> 0 | R40: =Q40 -> 0 | T40: {=IF(OR(ISBLANK(K38),ISBLANK(K39),ISBLANK(N39),ISBLANK(N40),ISBLANK(N41)),"",INDEX(INDEX('(Linked) PLr Probability Factor'!C$33:$F$44,0,4),MATCH(S38&S39&S42,INDEX('(Linked) PLr Probability Factor'!C$33:$F$44,0,1)&INDEX('(Linked) PLr Probability Factor'!C$33:$F$44,0,2)&INDEX('(Linked) PLr Probability Factor'!C$33:$F$44,0,3),0)))} | V40: Almost impossible, possible only under extreme circumstances | W40: =IF(ISBLANK(V40),"",VLOOKUP(V40,'(Linked) Hazard Risk Number HRN'!$D$6:$E$14,2,FALSE)) | X40: =IF(OR(ISBLANK(V38),ISBLANK(V39),ISBLANK(V40),ISBLANK(V41)),"",W38*W39*W40*W41) | Z40: Almost impossible, possible only under extreme circumstances | AA40: =IF(ISBLANK(Z40),"",VLOOKUP(Z40,'(Linked) Hazard Risk Number HRN'!$D$6:$E$14,2,FALSE)) | AB40: =IF(OR(ISBLANK(Z38),ISBLANK(Z39),ISBLANK(Z40),ISBLANK(Z41)),"",AA38*AA39*AA40*AA41) | AE40: Almost impossible, possible only under extreme circumstances | AF40: =IF(ISBLANK(AE40),"",VLOOKUP(AE40,'(Linked) Hazard Risk Number HRN'!$D$6:$E$14,2,FALSE)) | AG40: =IF(OR(ISBLANK(AE38),ISBLANK(AE39),ISBLANK(AE40),ISBLANK(AE41)),"",AF38*AF39*AF40*AF41)
K41: 1 to 2 persons | L41: =IF(ISBLANK(K41),"",VLOOKUP(K41,'(Linked) Hazard Risk Number HRN'!$D$17:$E$22,2,FALSE)) | N41: Easy recognition of the hazard (possible in ≥ 50% of the cases) | O41: =IF(ISBLANK(N41),"",VLOOKUP(N41,'(Linked) PLr Probability Factor'!$B$23:$C$26,2,FALSE)) | P41: Total | Q41: =SUM(R38:R40) -> 0 | R41: =Q41 -> 0 | V41: 1 to 2 persons | W41: =IF(ISBLANK(V41),"",VLOOKUP(V41,'(Linked) Hazard Risk Number HRN'!$D$17:$E$22,2,FALSE)) | Z41: 1 to 2 persons | AA41: =IF(ISBLANK(Z41),"",VLOOKUP(Z41,'(Linked) Hazard Risk Number HRN'!$D$17:$E$22,2,FALSE)) | AE41: 1 to 2 persons | AF41: =IF(ISBLANK(AE41),"",VLOOKUP(AE41,'(Linked) Hazard Risk Number HRN'!$D$17:$E$22,2,FALSE))
N42: Medium to high complexity (e.g. troubleshooting, hold-to-run setup) | O42: =IF(ISBLANK(N42),"",VLOOKUP(N42,'(Linked) PLr Probability Factor'!$B$29:$C$32,2,FALSE)) | S42: =IF(OR(ISBLANK(N39),ISBLANK(N40),ISBLANK(N41)),"",IF(R38>0,"P2",IF(AND(R38=0,R39>2),"P2",IF(AND(R38=0,R39=2),"P2",IF(AND(R38=0,AND(R39<2,R40>1)),"P1"," ")))))
...

Sheet ActionLog
A1: REEVALUACIÓN CON LAS SALVAGUARDAS EXISTENTES | G1: CONTROLES PROPUESTOS PARA REDUCIR EL RIESGO A UN NIVEL ACEPTABLE | H1: ELEMENTOS DE ACCIÓN
A2: HAZARD # | B2: Condition of Use (TASK) | C2: Hazard(s) / Failure Mode | D2: Mitigación actual | E2: HRN actual | F2: Nivel de riesgo actual | G2: Mitigación propuesta | H2: Comentarios, plan de acción, actualizaciones. | I2: Propietario de la tarea | J2: Fecha objetivo | K2: Fecha real | L2: Estado
A3: =IF(ISBLANK('MRA Full Assessment'!B8),"",'MRA Full Assessment'!B8) -> 1 | B3: =IF(ISBLANK('MRA Full Assessment'!C8),"",'MRA Full Assessment'!C8) | C3: =IF(ISBLANK('MRA Full Assessment'!D8),"",'MRA Full Assessment'!D8) | D3: =IF(ISBLANK('MRA Full Assessment'!E8),"",'MRA Full Assessment'!E8) | E3: =IF(ISBLANK('MRA Full Assessment'!F8),"",'MRA Full Assessment'!F8) | F3: =IF(ISBLANK('MRA Full Assessment'!G8),"",'MRA Full Assessment'!G8) | G3: =IF(ISBLANK('MRA Full Assessment'!H8),"",'MRA Full Assessment'!H8) | H3: =IF(ISBLANK('MRA Full Assessment'!I8),"",'MRA Full Assessment'!I8) | ... L3: =IF(ISBLANK('MRA Full Assessment'!M8),"",'MRA Full Assessment'!M8)
A4: =IF(ISBLANK('MRA Full Assessment'!B13),"",'MRA Full Assessment'!B13) -> 2 | B4: =IF(ISBLANK('MRA Full Assessment'!C9),"",'MRA Full Assessment'!C9) | C4: =IF(ISBLANK('MRA Full Assessment'!D9),"",'MRA Full Assessment'!D9) | D4: =IF(ISBLANK('MRA Full Assessment'!E9),"",'MRA Full Assessment'!E9) | E4: =IF(ISBLANK('MRA Full Assessment'!F9),"",'MRA Full Assessment'!F9) | F4: =IF(ISBLANK('MRA Full Assessment'!G9),"",'MRA Full Assessment'!G9) | G4: =IF(ISBLANK('MRA Full Assessment'!H9),"",'MRA Full Assessment'!H9) | H4: =IF(ISBLANK('MRA Full Assessment'!I9),"",'MRA Full Assessment'!I9) | I4: =IF(ISBLANK('MRA Full Assessment'!J9),"",'MRA Full Assessment'!J9) | ... L4: =IF(ISBLANK('MRA Full Assessment'!M9),"",'MRA Full Assessment'!M9)
A5: =IF(ISBLANK('MRA Full Assessment'!B18),"",'MRA Full Assessment'!B18) -> 3 | B5: =IF(ISBLANK('MRA Full Assessment'!C10),"",'MRA Full Assessment'!C10) | C5: =IF(ISBLANK('MRA Full Assessment'!D10),"",'MRA Full Assessment'!D10) | D5: =IF(ISBLANK('MRA Full Assessment'!E10),"",'MRA Full Assessment'!E10) | E5: =IF(ISBLANK('MRA Full Assessment'!F10),"",'MRA Full Assessment'!F10) | F5: =IF(ISBLANK('MRA Full Assessment'!G10),"",'MRA Full Assessment'!G10) | G5: =IF(ISBLANK('MRA Full Assessment'!H10),"",'MRA Full Assessment'!H10) | H5: =IF(ISBLANK('MRA Full Assessment'!I10),"",'MRA Full Assessment'!I10) | I5: =IF(ISBLANK('MRA Full Assessment'!J10),"",'MRA Full Assessment'!J10) | ... L5: =IF(ISBLANK('MRA Full Assessment'!M10),"",'MRA Full Assessment'!M10)
A6: =IF(ISBLANK('MRA Full Assessment'!B23),"",'MRA Full Assessment'!B23) -> 4 | B6: =IF(ISBLANK('MRA Full Assessment'!C11),"",'MRA Full Assessment'!C11) | C6: =IF(ISBLANK('MRA Full Assessment'!D11),"",'MRA Full Assessment'!D11) | D6: =IF(ISBLANK('MRA Full Assessment'!E11),"",'MRA Full Assessment'!E11) | E6: =IF(ISBLANK('MRA Full Assessment'!F11),"",'MRA Full Assessment'!F11) | F6: =IF(ISBLANK('MRA Full Assessment'!G11),"",'MRA Full Assessment'!G11) | G6: =IF(ISBLANK('MRA Full Assessment'!H11),"",'MRA Full Assessment'!H11) | H6: =IF(ISBLANK('MRA Full Assessment'!I11),"",'MRA Full Assessment'!I11) | I6: =IF(ISBLANK('MRA Full Assessment'!J11),"",'MRA Full Assessment'!J11) | ... L6: =IF(ISBLANK('MRA Full Assessment'!M11),"",'MRA Full Assessment'!M11)
A7: =IF(ISBLANK('MRA Full Assessment'!B28),"",'MRA Full Assessment'!B28) -> 5 | B7: =IF(ISBLANK('MRA Full Assessment'!C12),"",'MRA Full Assessment'!C12) | C7: =IF(ISBLANK('MRA Full Assessment'!D12),"",'MRA Full Assessment'!D12) | D7: =IF(ISBLANK('MRA Full Assessment'!E12),"",'MRA Full Assessment'!E12) | E7: =IF(ISBLANK('MRA Full Assessment'!F12),"",'MRA Full Assessment'!F12) | F7: =IF(ISBLANK('MRA Full Assessment'!G12),"",'MRA Full Assessment'!G12) | G7: =IF(ISBLANK('MRA Full Assessment'!H12),"",'MRA Full Assessment'!H12) | H7: =IF(ISBLANK('MRA Full Assessment'!I12),"",'MRA Full Assessment'!I12) | I7: =IF(ISBLANK('MRA Full Assessment'!J12),"",'MRA Full Assessment'!J12) | ... L7: =IF(ISBLANK('MRA Full Assessment'!M12),"",'MRA Full Assessment'!M12)
